Workbook

Sheet 元データ
A1: 店舗名 | B1: 年区分 | C1: 月 | D1: 項目 | E1: 売上金額 | F1: 商品点数 | G1: 客数 | H1: 利用数 | J1: ■入力ルール
A2: Ｃ新沢田店 | B2: 前年 | C2: 1 | D2: 全体 | E2: 1239567 | F2: 2825 | G2: 765 | J2: 1行 = 1店舗 × 1ヶ月 × 1項目
A3: Ｃ新沢田店 | B3: 前年 | C3: 1 | D3: ワイシャツ | F3: 1181 | J3: 年区分：本年 / 前年
A4: Ｃ新沢田店 | B4: 前年 | C4: 1 | D4: ズボン | F4: 461 | J4: 月：8,9,10,11,12,1,2,3,4,5,6,7（8月〜7月年度）
A5: Ｃ新沢田店 | B5: 前年 | C5: 1 | D5: ジャケット | F5: 371 | J5: 項目：全体 / ワイシャツ / ズボン / ジャケット / アプリ / BD / ダイヤモンド
A6: Ｃ新沢田店 | B6: 本年 | C6: 1 | D6: 全体 | E6: 1215172 | F6: 2546 | G6: 714 | J6: E〜H列に4指標の実績を入力
A7: Ｃ新沢田店 | B7: 本年 | C7: 1 | D7: ワイシャツ | F7: 968 | J7: 行はいくら増やしてもOK（20000行まで自動集計）
A8: Ｃ新沢田店 | B8: 本年 | C8: 1 | D8: ズボン | F8: 434 | J8: 店舗名は「店舗マスタ」と一致させてください
A9: Ｃ新沢田店 | B9: 本年 | C9: 1 | D9: ジャケット | F9: 389
A10: Ｃ新沢田店 | B10: 本年 | C10: 1 | D10: アプリ | H10: 115
A11: Ｃ新沢田店 | B11: 本年 | C11: 1 | D11: BD | H11: 4
A12: Ｃ新沢田店 | B12: 本年 | C12: 1 | D12: ダイヤモンド
A13: Ｃ新沢田店 | B13: 前年 | C13: 2 | D13: 全体 | E13: 1198353 | F13: 2593 | G13: 758
A14: Ｃ新沢田店 | B14: 前年 | C14: 2 | D14: ワイシャツ | F14: 1135
A15: Ｃ新沢田店 | B15: 前年 | C15: 2 | D15: ズボン | F15: 383
A16: Ｃ新沢田店 | B16: 前年 | C16: 2 | D16: ジャケット | F16: 301
A17: Ｃ新沢田店 | B17: 本年 | C17: 2 | D17: 全体 | E17: 1161376 | F17: 2356 | G17: 694
A18: Ｃ新沢田店 | B18: 本年 | C18: 2 | D18: ワイシャツ | F18: 975
A19: Ｃ新沢田店 | B19: 本年 | C19: 2 | D19: ズボン | F19: 371
A20: Ｃ新沢田店 | B20: 本年 | C20: 2 | D20: ジャケット | F20: 274
A21: Ｃ新沢田店 | B21: 本年 | C21: 2 | D21: アプリ
A22: Ｃ新沢田店 | B22: 本年 | C22: 2 | D22: BD
A23: Ｃ新沢田店 | B23: 本年 | C23: 2 | D23: ダイヤモンド
A24: Ｃ新沢田店 | B24: 前年 | C24: 3 | D24: 全体 | E24: 2478355 | F24: 4371 | G24: 845
A25: Ｃ新沢田店 | B25: 前年 | C25: 3 | D25: ワイシャツ | F25: 1346
A26: Ｃ新沢田店 | B26: 前年 | C26: 3 | D26: ズボン | F26: 554
A27: Ｃ新沢田店 | B27: 前年 | C27: 3 | D27: ジャケット | F27: 535
A28: Ｃ新沢田店 | B28: 本年 | C28: 3 | D28: 全体 | E28: 2070109 | F28: 3590
A29: Ｃ新沢田店 | B29: 本年 | C29: 3 | D29: ワイシャツ | F29: 1202
A30: Ｃ新沢田店 | B30: 本年 | C30: 3 | D30: ズボン | F30: 549
A31: Ｃ新沢田店 | B31: 本年 | C31: 3 | D31: ジャケット | F31: 499
A32: Ｃ新沢田店 | B32: 本年 | C32: 3 | D32: アプリ
A33: Ｃ新沢田店 | B33: 本年 | C33: 3 | D33: BD
A34: Ｃ新沢田店 | B34: 本年 | C34: 3 | D34: ダイヤモンド
A35: Ｃ新沢田店 | B35: 前年 | C35: 4 | D35: 全体 | E35: 3583762 | F35: 5692 | G35: 1472
A36: Ｃ新沢田店 | B36: 前年 | C36: 4 | D36: ワイシャツ | F36: 1470
A37: Ｃ新沢田店 | B37: 前年 | C37: 4 | D37: ズボン | F37: 738
A38: Ｃ新沢田店 | B38: 前年 | C38: 4 | D38: ジャケット | F38: 660
A39: Ｃ新沢田店 | B39: 本年 | C39: 4 | D39: 全体 | E39: 3609518 | F39: 5755 | G39: 1462
A40: Ｃ新沢田店 | B40: 本年 | C40: 4 | D40: ワイシャツ | F40: 1258
...

Sheet 元データ_14項目
A1: 店舗名 | B1: 年区分 | C1: 月 | D1: ワイシャツ | E1: カジュアルシャツ | F1: ブラウス | G1: スーツ | H1: 上着 | I1: ズボン | J1: スカート | K1: セーター | L1: カーディガン | M1: ワンピース | N1: コート | O1: ジャンバー | P1: ダウン | Q1: スキーウェア
A2: Ｃ新沢田店 | B2: 本年 | C2: 1 | D2: 968 | E2: 32 | F2: 34 | G2: 182 | H2: 14 | I2: 130 | J2: 28 | K2: 98 | L2: 19 | M2: 23 | N2: 52 | O2: 48 | P2: 10 | Q2: 7
A3: Ｃ新沢田店 | B3: 前年 | C3: 1 | D3: 1181 | E3: 46 | F3: 22 | G3: 185 | H3: 15 | I3: 123 | J3: 22 | K3: 92 | L3: 21 | M3: 26 | N3: 56 | O3: 31 | P3: 18 | Q3: 2
A4: Ｃ新沢田店 | B4: 本年 | C4: 2 | D4: 975 | E4: 25 | F4: 28 | G4: 104 | H4: 50 | I4: 166 | J4: 11 | K4: 71 | L4: 21 | M4: 24 | N4: 47 | O4: 31 | P4: 20 | Q4: 2
A5: Ｃ新沢田店 | B5: 前年 | C5: 2 | D5: 1135 | E5: 29 | F5: 26 | G5: 81 | H5: 57 | I5: 199 | J5: 20 | K5: 124 | L5: 26 | M5: 19 | N5: 62 | O5: 22 | P5: 17 | Q5: 2
A6: Ｃ新沢田店 | B6: 本年 | C6: 3 | D6: 1202 | E6: 54 | F6: 44 | G6: 203 | H6: 22 | I6: 177 | J6: 24 | K6: 134 | L6: 27 | M6: 22 | N6: 160 | O6: 111 | P6: 110 | Q6: 5
A7: Ｃ新沢田店 | B7: 前年 | C7: 3 | D7: 1346 | E7: 45 | F7: 51 | G7: 209 | H7: 38 | I7: 188 | J7: 26 | K7: 194 | L7: 58 | M7: 29 | N7: 272 | O7: 129 | P7: 202 | Q7: 18
A8: Ｃ新沢田店 | B8: 本年 | C8: 4 | D8: 1258 | E8: 90 | F8: 80 | G8: 273 | H8: 50 | I8: 285 | J8: 68 | K8: 499 | L8: 171 | M8: 71 | N8: 539 | O8: 210 | P8: 256 | Q8: 10
A9: Ｃ新沢田店 | B9: 前年 | C9: 4 | D9: 1470 | E9: 48 | F9: 52 | G9: 248 | H9: 56 | I9: 265 | J9: 68 | K9: 497 | L9: 161 | M9: 62 | N9: 491 | O9: 194 | P9: 221 | Q9: 11
A10: Ｃ新沢田店 | B10: 本年 | C10: 5 | D10: 980 | E10: 79 | F10: 73 | G10: 216 | H10: 62 | I10: 241 | J10: 41 | K10: 245 | L10: 127 | M10: 44 | N10: 228 | O10: 154 | P10: 134 | Q10: 6
A11: Ｃ新沢田店 | B11: 前年 | C11: 5 | D11: 1229 | E11: 104 | F11: 85 | G11: 224 | H11: 46 | I11: 277 | J11: 61 | K11: 333 | L11: 126 | M11: 61 | N11: 275 | O11: 212 | P11: 142 | Q11: 7
A12: Ｃ新沢田店 | B12: 本年 | C12: 6 | D12: 1146 | E12: 87 | F12: 92 | G12: 156 | H12: 64 | I12: 325 | J12: 62 | K12: 191 | L12: 96 | M12: 53 | N12: 148 | O12: 109 | P12: 74 | Q12: 2
A13: Ｃ新沢田店 | B13: 前年 | C13: 6 | D13: 1205 | E13: 95 | F13: 73 | G13: 169 | H13: 49 | I13: 310 | J13: 43 | K13: 148 | L13: 123 | M13: 48 | N13: 158 | O13: 116 | P13: 66 | Q13: 1
... A650: 城北店 | B650: 本年 | C650: 8 | D650: 767 | E650: 11 | F650: 30 | G650: 49 | H650: 13 | I650: 199 | J650: 10 | K650: 14 | L650: 15 | M650: 14 | N650: 8 | O650: 19 | P650: 14 | Q650: 0
A651: 城北店 | B651: 前年 | C651: 8 | D651: 893 | E651: 13 | F651: 26 | G651: 69 | H651: 18 | I651: 238 | J651: 18 | K651: 37 | L651: 15 | M651: 18 | N651: 10 | O651: 32 | P651: 7
A652: 城北店 | B652: 本年 | C652: 9 | D652: 1011 | E652: 14 | F652: 30 | G652: 57 | H652: 29 | I652: 198 | J652: 24 | K652: 20 | L652: 9 | M652: 32 | N652: 11 | O652: 13 | P652: 6 | Q652: 2
A653: 城北店 | B653: 前年 | C653: 9 | D653: 944 | E653: 7 | F653: 39 | G653: 52 | H653: 11 | I653: 190 | J653: 21 | K653: 14 | L653: 11 | M653: 18 | N653: 7 | O653: 24 | P653: 4 | Q653: 0
A654: 城北店 | B654: 本年 | C654: 10 | D654: 1062 | E654: 21 | F654: 67 | G654: 60 | H654: 76 | I654: 316 | J654: 38 | K654: 27 | L654: 23 | M654: 49 | N654: 40 | O654: 31 | P654: 19 | Q654: 0
A655: 城北店 | B655: 前年 | C655: 10 | D655: 1422 | E655: 35 | F655: 58 | G655: 134 | H655: 35 | I655: 329 | J655: 55 | K655: 62 | L655: 31 | M655: 38 | N655: 31 | O655: 25 | P655: 11 | Q655: 4
A656: 城北店 | B656: 本年 | C656: 11 | D656: 990 | E656: 26 | F656: 69 | G656: 113 | H656: 78 | I656: 244 | J656: 33 | K656: 36 | L656: 26 | M656: 38 | N656: 29 | O656: 27 | P656: 20 | Q656: 0
A657: 城北店 | B657: 前年 | C657: 11 | D657: 1162 | E657: 44 | F657: 32 | G657: 132 | H657: 42 | I657: 248 | J657: 16 | K657: 47 | L657: 12 | M657: 40 | N657: 28 | O657: 27 | P657: 12 | Q657: 0
A658: 城北店 | B658: 本年 | C658: 12 | D658: 1126 | E658: 28 | F658: 34 | G658: 132 | H658: 41 | I658: 176 | J658: 19 | K658: 76 | L658: 23 | M658: 16 | N658: 40 | O658: 38 | P658: 13 | Q658: 2
A659: 城北店 | B659: 前年 | C659: 12 | D659: 1270 | E659: 32 | F659: 32 | G659: 213 | H659: 32 | I659: 238 | J659: 21 | K659: 89 | L659: 26 | M659: 22 | N659: 30 | O659: 37 | P659: 15 | Q659: 2
A660: 神山店 | B660: 本年 | C660: 1 | D660: 392 | E660: 21 | F660: 11 | G660: 55 | H660: 0 | I660: 37 | J660: 6 | K660: 17 | L660: 6 | M660: 13 | N660: 23 | O660: 18 | P660: 7 | Q660: 0
A661: 神山店 | B661: 前年 | C661: 1 | D661: 337 | E661: 22 | F661: 8 | G661: 44 | H661: 2 | I661: 70 | J661: 9 | K661: 24 | L661: 6 | M661: 8 | N661: 33 | O661: 14 | P661: 9 | Q661: 0
A662: 神山店 | B662: 本年 | C662: 2 | D662: 365 | E662: 26 | F662: 6 | G662: 35 | H662: 1 | I662: 45 | J662: 9 | K662: 19 | L662: 10 | M662: 7 | N662: 18 | O662: 14 | P662: 6 | Q662: 2
A663: 神山店 | B663: 前年 | C663: 2 | D663: 374 | E663: 24 | F663: 12 | G663: 19 | H663: 16 | I663: 67 | J663: 11 | K663: 18 | L663: 6 | M663: 13 | N663: 20 | O663: 9 | P663: 9 | Q663: 0
... A1235: 与惣次店 | B1235: 前年 | C1235: 12 | D1235: 882 | E1235: 27 | F1235: 38 | G1235: 190 | H1235: 25 | I1235: 196 | J1235: 58 | K1235: 73 | L1235: 44 | M1235: 42 | N1235: 42 | O1235: 44 | P1235: 16 | Q1235: 0

Sheet 元データ_加工
A1: 店舗名 | B1: 月 | C1: ドライ点数 | D1: ＹシャツＳコース点数 | E1: 花粉加工 | F1: スーパーリボーン加工 | G1: 撥水加工 | H1: 防虫加工 | I1: 爽快 | J1: エコウェット | K1: 防臭加工 | L1: 念入り | M1: なめらかタッチ | N1: 布団類防虫 | O1: 襟・袖念入り | P1: 復元
A2: Ｃ新沢田店 | B2: 1 | C2: 1578 | D2: 968 | E2: 0 | F2: 18 | G2: 9 | H2: 4 | I2: 148 | J2: 5 | K2: 10 | L2: 37 | M2: 0 | N2: 0 | O2: 0 | P2: 0
A3: Ｃ新沢田店 | B3: 2 | C3: 1381 | D3: 975 | E3: 0 | F3: 16 | G3: 14 | H3: 0 | I3: 126 | J3: 0 | K3: 1 | L3: 39 | M3: 0 | N3: 0 | O3: 2 | P3: 2
A4: Ｃ新沢田店 | B4: 3 | C4: 2388 | D4: 1202 | E4: 4 | F4: 14 | G4: 55 | H4: 21 | I4: 223 | J4: 0 | K4: 0 | L4: 31 | M4: 0 | N4: 0 | O4: 4 | P4: 5
A5: Ｃ新沢田店 | B5: 4 | C5: 4497 | D5: 1258 | E5: 0 | F5: 28 | G5: 61 | H5: 60 | I5: 239 | J5: 2 | K5: 0 | L5: 33 | M5: 0 | N5: 0 | O5: 3 | P5: 9
A6: Ｃ新沢田店 | B6: 5 | C6: 2887 | D6: 980 | E6: 0 | F6: 0 | G6: 19 | H6: 35 | I6: 167 | J6: 0 | K6: 0 | L6: 15 | M6: 0 | N6: 0 | O6: 0 | P6: 8
A7: Ｃ新沢田店 | B7: 6 | C7: 2772 | D7: 1146 | E7: 0 | F7: 0 | G7: 35 | H7: 16 | I7: 261 | J7: 2 | K7: 1 | L7: 23 | M7: 0 | N7: 0 | O7: 1 | P7: 1
A8: Ｃ新沢田店 | B8: 7 | C8: 2053 | D8: 1018 | E8: 0 | F8: 0 | G8: 10 | H8: 23 | I8: 346 | J8: 9 | K8: 0 | L8: 27 | M8: 0 | N8: 0 | O8: 0 | P8: 3
A9: Ｃ新沢田店 | B9: 8 | C9: 1362 | D9: 831 | E9: 0 | F9: 0 | G9: 10 | H9: 0 | I9: 227 | J9: 9 | K9: 0 | L9: 33 | M9: 0 | N9: 0 | O9: 0 | P9: 4
A10: Ｃ新沢田店 | B10: 9 | C10: 1500 | D10: 1003 | E10: 0 | F10: 0 | G10: 9 | H10: 0 | I10: 195 | J10: 9 | K10: 4 | L10: 29 | M10: 0 | N10: 0 | O10: 0 | P10: 1
A11: Ｃ新沢田店 | B11: 10 | C11: 2469 | D11: 1325 | E11: 0 | F11: 0 | G11: 12 | H11: 0 | I11: 294 | J11: 11 | K11: 1 | L11: 61 | M11: 0 | N11: 0 | O11: 0
A12: Ｃ新沢田店 | B12: 11 | C12: 2206 | D12: 1225 | E12: 0 | F12: 4 | G12: 8 | H12: 0 | I12: 202 | J12: 5 | K12: 20 | L12: 43 | M12: 0 | N12: 0 | O12: 0 | P12: 2
A13: Ｃ新沢田店 | B13: 12 | C13: 2287 | D13: 1186 | E13: 0 | F13: 9 | G13: 27 | H13: 0 | I13: 230 | J13: 2 | K13: 10 | L13: 47 | M13: 0 | N13: 0 | O13: 0 | P13: 2
A14: Ｋ函南店 | B14: 1 | C14: 1849 | D14: 1211 | E14: 0 | F14: 7 | G14: 17 | H14: 9 | I14: 176 | J14: 0 | K14: 61 | L14: 19 | M14: 0 | N14: 0 | O14: 0 | P14: 2
A15: Ｋ函南店 | B15: 2 | C15: 1606 | D15: 1265 | E15: 0 | F15: 9 | G15: 34 | H15: 2 | I15: 186 | J15: 0 | K15: 71 | L15: 6 | M15: 0 | N15: 0 | O15: 0 | P15: 2
A16: Ｋ函南店 | B16: 3 | C16: 3256 | D16: 1448 | E16: 0 | F16: 2 | G16: 136 | H16: 36 | I16: 253 | J16: 1 | K16: 36 | L16: 13 | M16: 0 | N16: 0 | O16: 0 | P16: 2
A17: Ｋ函南店 | B17: 4 | C17: 5568 | D17: 1516 | E17: 0 | F17: 1 | G17: 151 | H17: 120 | I17: 337 | J17: 3 | K17: 19 | L17: 6 | M17: 0 | N17: 0 | O17: 1
A18: Ｋ函南店 | B18: 5 | C18: 3609 | D18: 1417 | E18: 0 | F18: 0 | G18: 70 | H18: 63 | I18: 269 | J18: 2 | K18: 49 | L18: 6 | M18: 0 | N18: 0 | O18: 1
A19: Ｋ函南店 | B19: 6 | C19: 3106 | D19: 1453 | E19: 0 | F19: 0 | G19: 80 | H19: 39 | I19: 380 | J19: 1 | K19: 35 | L19: 19 | M19: 0 | N19: 0 | O19: 0
A20: Ｋ函南店 | B20: 7 | C20: 2383 | D20: 1332 | E20: 0 | F20: 0 | G20: 86 | H20: 16 | I20: 484 | J20: 4 | K20: 5 | L20: 4 | M20: 0 | N20: 1 | O20: 0
A21: Ｋ函南店 | B21: 8 | C21: 2125 | D21: 1166 | E21: 2 | F21: 0 | G21: 49 | H21: 15 | I21: 527 | J21: 2 | K21: 8 | L21: 16 | M21: 0 | N21: 0 | O21: 0
A22: Ｋ函南店 | B22: 9 | C22: 1994 | D22: 1261 | E22: 0 | F22: 0 | G22: 38 | H22: 4 | I22: 400 | J22: 4 | K22: 22 | L22: 20 | M22: 0 | N22: 0 | O22: 0
A23: Ｋ函南店 | B23: 10 | C23: 2971 | D23: 1624 | E23: 0 | F23: 0 | G23: 57 | H23: 9 | I23: 415 | J23: 1 | K23: 66 | L23: 32 | M23: 0 | N23: 0 | O23: 0
A24: Ｋ函南店 | B24: 11 | C24: 2594 | D24: 1452 | E24: 0 | F24: 8 | G24: 34 | H24: 18 | I24: 370 | J24: 0 | K24: 93 | L24: 20 | M24: 0 | N24: 0 | O24: 0
A25: Ｋ函南店 | B25: 12 | C25: 2589 | D25: 1417 | E25: 0 | F25: 11 | G25: 94 | H25: 4 | I25: 322 | J25: 1 | K25: 74 | L25: 21 | M25: 0 | N25: 0 | O25: 0
A26: ＭＶ原町店 | B26: 1 | C26: 795 | D26: 328 | E26: 0 | F26: 11 | G26: 16 | H26: 1 | I26: 62 | J26: 45 | K26: 11 | L26: 41 | M26: 0 | N26: 0 | O26: 0
A27: ＭＶ原町店 | B27: 2 | C27: 744 | D27: 384 | E27: 0 | F27: 12 | G27: 10 | H27: 2 | I27: 60 | J27: 43 | K27: 4 | L27: 51 | M27: 0 | N27: 0 | O27: 0
A28: ＭＶ原町店 | B28: 3 | C28: 1456 | D28: 430 | E28: 0 | F28: 0 | G28: 68 | H28: 36 | I28: 148 | J28: 73 | K28: 12 | L28: 51 | M28: 0 | N28: 0 | O28: 0
... A144: 吉田店 | B144: 12 | C144: 1786 | D144: 661 | E144: 0 | F144: 36 | G144: 115 | H144: 7 | I144: 500 | J144: 0 | K144: 95 | L144: 209 | M144: 0 | N144: 0 | O144: 0
A145: 曲金店 | B145: 1 | C145: 708 | D145: 666 | E145: 0 | F145: 2 | G145: 10 | H145: 1 | I145: 63 | J145: 8 | K145: 2 | L145: 33 | M145: 0 | N145: 0 | O145: 1 | P145: 1
A146: 曲金店 | B146: 2 | C146: 621 | D146: 731 | E146: 2 | F146: 0 | G146: 23 | H146: 8 | I146: 67 | J146: 13 | K146: 0 | L146: 71 | M146: 0 | N146: 0 | O146: 0 | P146: 0
A147: 曲金店 | B147: 3 | C147: 1330 | D147: 889 | E147: 0 | F147: 2 | G147: 34 | H147: 12 | I147: 127 | J147: 11 | K147: 8 | L147: 66 | M147: 0 | N147: 0 | O147: 0 | P147: 1
A148: 曲金店 | B148: 4 | C148: 2342 | D148: 947 | E148: 2 | F148: 1 | G148: 60 | H148: 50 | I148: 225 | J148: 11 | K148: 0 | L148: 85 | M148: 0 | N148: 0 | O148: 3 | P148: 4
A149: 曲金店 | B149: 5 | C149: 1523 | D149: 775 | E149: 0 | F149: 0 | G149: 33 | H149: 17 | I149: 185 | J149: 20 | K149: 0 | L149: 38 | M149: 0 | N149: 0 | O149: 0 | P149: 1
A150: 曲金店 | B150: 6 | C150: 1304 | D150: 1007 | E150: 0 | F150: 4 | G150: 19 | H150: 6 | I150: 154 | J150: 18 | K150: 13 | L150: 59 | M150: 0 | N150: 0 | O150: 4 | P150: 5
A151: 曲金店 | B151: 7 | C151: 864 | D151: 757 | E151: 0 | F151: 0 | G151: 13 | H151: 10 | I151: 141 | J151: 39 | K151: 0 | L151: 40 | M151: 0 | N151: 0 | O151: 0 | P151: 3
A152: 曲金店 | B152: 8 | C152: 644 | D152: 621 | E152: 0 | F152: 0 | G152: 6 | H152: 0 | I152: 142 | J152: 29 | K152: 0 | L152: 48 | M152: 0 | N152: 0 | O152: 0
A153: 曲金店 | B153: 9 | C153: 656 | D153: 777 | E153: 0 | F153: 0 | G153: 5 | H153: 4 | I153: 101 | J153: 39 | K153: 3 | L153: 70 | M153: 0 | N153: 0 | O153: 0 | P153: 0
A154: 曲金店 | B154: 10 | C154: 1035 | D154: 1022 | E154: 0 | F154: 0 | G154: 12 | H154: 11 | I154: 196 | J154: 31 | K154: 36 | L154: 120 | M154: 0 | N154: 0 | O154: 1 | P154: 5
A155: 曲金店 | B155: 11 | C155: 1072 | D155: 845 | E155: 0 | F155: 12 | G155: 23 | H155: 8 | I155: 153 | J155: 23 | K155: 11 | L155: 57 | M155: 0 | N155: 0 | O155: 2 | P155: 4
...

Sheet 店舗マスタ
A1: 店舗名 | C1: ※実際の店舗名に上書きしてください（各表に自動反映）
A2: 裾野本店
A3: 三 島 店
A4: ｱｰｹｰﾄﾞ店
A5: 東田中店
A6: 桜堤店
A7: 香貫店
A8: 学園通り店
A9: 伏見店
A10: 原里店
A11: 岡の宮店
A12: 川島田店
A13: 便船塚店
... A54: 竹原店

Sheet 1_昨対表
A1: 店舗別 年計表 ① 昨対表（8月〜7月）
A2: 指標 | C2: 売上金額
A3: 項目 | C3: 全体
C4: 本年 | P4: 前年 | AC4: 前年比
A5: 店舗名 | C5: 8 | D5: 9 | E5: 10 | F5: 11 | G5: 12 | H5: 1 | I5: 2 | J5: 3 | K5: 4 | L5: 5 | M5: 6 | N5: 7 | O5: 年計 | P5: 8 | Q5: 9 | R5: 10 | S5: 11 | T5: 12 | U5: 1 | V5: 2 | W5: 3 | X5: 4 | Y5: 5 | Z5: 6 | AA5: 7 | AB5: 年計 | AC5: 8 | AD5: 9 | AE5: 10 | AF5: 11 | AG5: 12 | AH5: 1 | AI5: 2 | AJ5: 3 | AK5: 4 | AL5: 5 | AM5: 6 | AN5: 7 | AO5: 年計
A6: =店舗マスタ!A2 -> 裾野本店 | C6: =SUMIFS(INDEX(元データ!$E$2:$H$20000,0,MATCH($C$2,元データ!$E$1:$H$1,0)),元データ!$A$2:$A$20000,$A6,元データ!$D$2:$D$20000,$C$3,元データ!$B$2:$B$20000,$C$4,元データ!$C$2:$C$20000,C$5) -> 1604809 | D6: =SUMIFS(INDEX(元データ!$E$2:$H$20000,0,MATCH($C$2,元データ!$E$1:$H$1,0)),元データ!$A$2:$A$20000,$A6,元データ!$D$2:$D$20000,$C$3,元データ!$B$2:$B$20000,$C$4,元データ!$C$2:$C$20000,D$5) -> 1533736 | E6: =SUMIFS(INDEX(元データ!$E$2:$H$20000,0,MATCH($C$2,元データ!$E$1:$H$1,0)),元データ!$A$2:$A$20000,$A6,元データ!$D$2:$D$20000,$C$3,元データ!$B$2:$B$20000,$C$4,元データ!$C$2:$C$20000,E$5) -> 2230848 | F6: =SUMIFS(INDEX(元データ!$E$2:$H$20000,0,MATCH($C$2,元データ!$E$1:$H$1,0)),元データ!$A$2:$A$20000,$A6,元データ!$D$2:$D$20000,$C$3,元データ!$B$2:$B$20000,$C$4,元データ!$C$2:$C$20000,F$5) -> 1799563 | G6: =SUMIFS(INDEX(元データ!$E$2:$H$20000,0,MATCH($C$2,元データ!$E$1:$H$1,0)),元データ!$A$2:$A$20000,$A6,元データ!$D$2:$D$20000,$C$3,元データ!$B$2:$B$20000,$C$4,元データ!$C$2:$C$20000,G$5) -> 2045741 | H6: =SUMIFS(INDEX(元データ!$E$2:$H$20000,0,MATCH($C$2,元データ!$E$1:$H$1,0)),元データ!$A$2:$A$20000,$A6,元データ!$D$2:$D$20000,$C$3,元データ!$B$2:$B$20000,$C$4,元データ!$C$2:$C$20000,H$5) -> 1397078 | I6: =SUMIFS(INDEX(元データ!$E$2:$H$20000,0,MATCH($C$2,元データ!$E$1:$H$1,0)),元データ!$A$2:$A$20000,$A6,元データ!$D$2:$D$20000,$C$3,元データ!$B$2:$B$20000,$C$4,元データ!$C$2:$C$20000,I$5) -> 1201074 | J6: =SUMIFS(INDEX(元データ!$E$2:$H$20000,0,MATCH($C$2,元データ!$E$1:$H$1,0)),元データ!$A$2:$A$20000,$A6,元データ!$D$2:$D$20000,$C$3,元データ!$B$2:$B$20000,$C$4,元データ!$C$2:$C$20000,J$5) -> 2346357 | ... N6: =SUMIFS(INDEX(元データ!$E$2:$H$20000,0,MATCH($C$2,元データ!$E$1:$H$1,0)),元データ!$A$2:$A$20000,$A6,元データ!$D$2:$D$20000,$C$3,元データ!$B$2:$B$20000,$C$4,元データ!$C$2:$C$20000,N$5) -> 1779152 | O6: =SUM(C6:N6) -> 24911731 | P6: =SUMIFS(INDEX(元データ!$E$2:$H$20000,0,MATCH($C$2,元データ!$E$1:$H$1,0)),元データ!$A$2:$A$20000,$A6,元データ!$D$2:$D$20000,$C$3,元データ!$B$2:$B$20000,$P$4,元データ!$C$2:$C$20000,P$5) -> 1669180 | Q6: =SUMIFS(INDEX(元データ!$E$2:$H$20000,0,MATCH($C$2,元データ!$E$1:$H$1,0)),元データ!$A$2:$A$20000,$A6,元データ!$D$2:$D$20000,$C$3,元データ!$B$2:$B$20000,$P$4,元データ!$C$2:$C$20000,Q$5) -> 1548475 | R6: =SUMIFS(INDEX(元データ!$E$2:$H$20000,0,MATCH($C$2,元データ!$E$1:$H$1,0)),元データ!$A$2:$A$20000,$A6,元データ!$D$2:$D$20000,$C$3,元データ!$B$2:$B$20000,$P$4,元データ!$C$2:$C$20000,R$5) -> 2365982 | S6: =SUMIFS(INDEX(元データ!$E$2:$H$20000,0,MATCH($C$2,元データ!$E$1:$H$1,0)),元データ!$A$2:$A$20000,$A6,元データ!$D$2:$D$20000,$C$3,元データ!$B$2:$B$20000,$P$4,元データ!$C$2:$C$20000,S$5) -> 1919453 | T6: =SUMIFS(INDEX(元データ!$E$2:$H$20000,0,MATCH($C$2,元データ!$E$1:$H$1,0)),元データ!$A$2:$A$20000,$A6,元データ!$D$2:$D$20000,$C$3,元データ!$B$2:$B$20000,$P$4,元データ!$C$2:$C$20000,T$5) -> 2183955 | U6: =SUMIFS(INDEX(元データ!$E$2:$H$20000,0,MATCH($C$2,元データ!$E$1:$H$1,0)),元データ!$A$2:$A$20000,$A6,元データ!$D$2:$D$20000,$C$3,元データ!$B$2:$B$20000,$P$4,元データ!$C$2:$C$20000,U$5) -> 1338289 | V6: =SUMIFS(INDEX(元データ!$E$2:$H$20000,0,MATCH($C$2,元データ!$E$1:$H$1,0)),元データ!$A$2:$A$20000,$A6,元データ!$D$2:$D$20000,$C$3,元データ!$B$2:$B$20000,$P$4,元データ!$C$2:$C$20000,V$5) -> 1368988 | W6: =SUMIFS(INDEX(元データ!$E$2:$H$20000,0,MATCH($C$2,元データ!$E$1:$H$1,0)),元データ!$A$2:$A$20000,$A6,元データ!$D$2:$D$20000,$C$3,元データ!$B$2:$B$20000,$P$4,元データ!$C$2:$C$20000,W$5) -> 3127025 | ... AA6: =SUMIFS(INDEX(元データ!$E$2:$H$20000,0,MATCH($C$2,元データ!$E$1:$H$1,0)),元データ!$A$2:$A$20000,$A6,元データ!$D$2:$D$20000,$C$3,元データ!$B$2:$B$20000,$P$4,元データ!$C$2:$C$20000,AA$5) -> 2040673 | AB6: =SUM(P6:AA6) -> 27324226 | AC6: =IFERROR(C6/P6,"") -> 0.96143556 | AD6: =IFERROR(D6/Q6,"") -> 0.9904816 | AE6: =IFERROR(E6/R6,"") -> 0.9428846 | AF6: =IFERROR(F6/S6,"") -> 0.9375395 | AG6: =IFERROR(G6/T6,"") -> 0.9367139 | AH6: =IFERROR(H6/U6,"") -> 1.0439285 | AI6: =IFERROR(I6/V6,"") -> 0.87734443 | AJ6: =IFERROR(J6/W6,"") -> 0.75034801 | ... AO6: =IFERROR(O6/AB6,"") -> 0.91170857
A7: =店舗マスタ!A3 -> 三 島 店 | C7: =SUMIFS(INDEX(元データ!$E$2:$H$20000,0,MATCH($C$2,元データ!$E$1:$H$1,0)),元データ!$A$2:$A$20000,$A7,元データ!$D$2:$D$20000,$C$3,元データ!$B$2:$B$20000,$C$4,元データ!$C$2:$C$20000,C$5) -> 1347241 | D7: =SUMIFS(INDEX(元データ!$E$2:$H$20000,0,MATCH($C$2,元データ!$E$1:$H$1,0)),元データ!$A$2:$A$20000,$A7,元データ!$D$2:$D$20000,$C$3,元データ!$B$2:$B$20000,$C$4,元データ!$C$2:$C$20000,D$5) -> 1377125 | E7: =SUMIFS(INDEX(元データ!$E$2:$H$20000,0,MATCH($C$2,元データ!$E$1:$H$1,0)),元データ!$A$2:$A$20000,$A7,元データ!$D$2:$D$20000,$C$3,元データ!$B$2:$B$20000,$C$4,元データ!$C$2:$C$20000,E$5) -> 1916787 | F7: =SUMIFS(INDEX(元データ!$E$2:$H$20000,0,MATCH($C$2,元データ!$E$1:$H$1,0)),元データ!$A$2:$A$20000,$A7,元データ!$D$2:$D$20000,$C$3,元データ!$B$2:$B$20000,$C$4,元データ!$C$2:$C$20000,F$5) -> 1778551 | G7: =SUMIFS(INDEX(元データ!$E$2:$H$20000,0,MATCH($C$2,元データ!$E$1:$H$1,0)),元データ!$A$2:$A$20000,$A7,元データ!$D$2:$D$20000,$C$3,元データ!$B$2:$B$20000,$C$4,元データ!$C$2:$C$20000,G$5) -> 1675687 | H7: =SUMIFS(INDEX(元データ!$E$2:$H$20000,0,MATCH($C$2,元データ!$E$1:$H$1,0)),元データ!$A$2:$A$20000,$A7,元データ!$D$2:$D$20000,$C$3,元データ!$B$2:$B$20000,$C$4,元データ!$C$2:$C$20000,H$5) -> 1048452 | I7: =SUMIFS(INDEX(元データ!$E$2:$H$20000,0,MATCH($C$2,元データ!$E$1:$H$1,0)),元データ!$A$2:$A$20000,$A7,元データ!$D$2:$D$20000,$C$3,元データ!$B$2:$B$20000,$C$4,元データ!$C$2:$C$20000,I$5) -> 966925 | J7: =SUMIFS(INDEX(元データ!$E$2:$H$20000,0,MATCH($C$2,元データ!$E$1:$H$1,0)),元データ!$A$2:$A$20000,$A7,元データ!$D$2:$D$20000,$C$3,元データ!$B$2:$B$20000,$C$4,元データ!$C$2:$C$20000,J$5) -> 2039609 | ... N7: =SUMIFS(INDEX(元データ!$E$2:$H$20000,0,MATCH($C$2,元データ!$E$1:$H$1,0)),元データ!$A$2:$A$20000,$A7,元データ!$D$2:$D$20000,$C$3,元データ!$B$2:$B$20000,$C$4,元データ!$C$2:$C$20000,N$5) -> 1514522 | O7: =SUM(C7:N7) -> 22078948 | P7: =SUMIFS(INDEX(元データ!$E$2:$H$20000,0,MATCH($C$2,元データ!$E$1:$H$1,0)),元データ!$A$2:$A$20000,$A7,元データ!$D$2:$D$20000,$C$3,元データ!$B$2:$B$20000,$P$4,元データ!$C$2:$C$20000,P$5) -> 1339195 | Q7: =SUMIFS(INDEX(元データ!$E$2:$H$20000,0,MATCH($C$2,元データ!$E$1:$H$1,0)),元データ!$A$2:$A$20000,$A7,元データ!$D$2:$D$20000,$C$3,元データ!$B$2:$B$20000,$P$4,元データ!$C$2:$C$20000,Q$5) -> 1346863 | R7: =SUMIFS(INDEX(元データ!$E$2:$H$20000,0,MATCH($C$2,元データ!$E$1:$H$1,0)),元データ!$A$2:$A$20000,$A7,元データ!$D$2:$D$20000,$C$3,元データ!$B$2:$B$20000,$P$4,元データ!$C$2:$C$20000,R$5) -> 1890120 | S7: =SUMIFS(INDEX(元データ!$E$2:$H$20000,0,MATCH($C$2,元データ!$E$1:$H$1,0)),元データ!$A$2:$A$20000,$A7,元データ!$D$2:$D$20000,$C$3,元データ!$B$2:$B$20000,$P$4,元データ!$C$2:$C$20000,S$5) -> 1651101 | T7: =SUMIFS(INDEX(元データ!$E$2:$H$20000,0,MATCH($C$2,元データ!$E$1:$H$1,0)),元データ!$A$2:$A$20000,$A7,元データ!$D$2:$D$20000,$C$3,元データ!$B$2:$B$20000,$P$4,元データ!$C$2:$C$20000,T$5) -> 2026432 | U7: =SUMIFS(INDEX(元データ!$E$2:$H$20000,0,MATCH($C$2,元データ!$E$1:$H$1,0)),元データ!$A$2:$A$20000,$A7,元データ!$D$2:$D$20000,$C$3,元データ!$B$2:$B$20000,$P$4,元データ!$C$2:$C$20000,U$5) -> 1110699 | V7: =SUMIFS(INDEX(元データ!$E$2:$H$20000,0,MATCH($C$2,元データ!$E$1:$H$1,0)),元データ!$A$2:$A$20000,$A7,元データ!$D$2:$D$20000,$C$3,元データ!$B$2:$B$20000,$P$4,元データ!$C$2:$C$20000,V$5) -> 1048670 | W7: =SUMIFS(INDEX(元データ!$E$2:$H$20000,0,MATCH($C$2,元データ!$E$1:$H$1,0)),元データ!$A$2:$A$20000,$A7,元データ!$D$2:$D$20000,$C$3,元データ!$B$2:$B$20000,$P$4,元データ!$C$2:$C$20000,W$5) -> 2504083 | ... AA7: =SUMIFS(INDEX(元データ!$E$2:$H$20000,0,MATCH($C$2,元データ!$E$1:$H$1,0)),元データ!$A$2:$A$20000,$A7,元データ!$D$2:$D$20000,$C$3,元データ!$B$2:$B$20000,$P$4,元データ!$C$2:$C$20000,AA$5) -> 1654677 | AB7: =SUM(P7:AA7) -> 23541322 | AC7: =IFERROR(C7/P7,"") -> 1.0060081 | AD7: =IFERROR(D7/Q7,"") -> 1.0224685 | AE7: =IFERROR(E7/R7,"") -> 1.0141086 | AF7: =IFERROR(F7/S7,"") -> 1.0771909 | AG7: =IFERROR(G7/T7,"") -> 0.82691499 | AH7: =IFERROR(H7/U7,"") -> 0.94395691 | AI7: =IFERROR(I7/V7,"") -> 0.92204888 | AJ7: =IFERROR(J7/W7,"") -> 0.81451334 | ... AO7: =IFERROR(O7/AB7,"") -> 0.93788055
A8: =店舗マスタ!A4 -> ｱｰｹｰﾄﾞ店 | C8: =SUMIFS(INDEX(元データ!$E$2:$H$20000,0,MATCH($C$2,元データ!$E$1:$H$1,0)),元データ!$A$2:$A$20000,$A8,元データ!$D$2:$D$20000,$C$3,元データ!$B$2:$B$20000,$C$4,元データ!$C$2:$C$20000,C$5) -> 710995 | D8: =SUMIFS(INDEX(元データ!$E$2:$H$20000,0,MATCH($C$2,元データ!$E$1:$H$1,0)),元データ!$A$2:$A$20000,$A8,元データ!$D$2:$D$20000,$C$3,元データ!$B$2:$B$20000,$C$4,元データ!$C$2:$C$20000,D$5) -> 706691 | E8: =SUMIFS(INDEX(元データ!$E$2:$H$20000,0,MATCH($C$2,元データ!$E$1:$H$1,0)),元データ!$A$2:$A$20000,$A8,元データ!$D$2:$D$20000,$C$3,元データ!$B$2:$B$20000,$C$4,元データ!$C$2:$C$20000,E$5) -> 1085550 | F8: =SUMIFS(INDEX(元データ!$E$2:$H$20000,0,MATCH($C$2,元データ!$E$1:$H$1,0)),元データ!$A$2:$A$20000,$A8,元データ!$D$2:$D$20000,$C$3,元データ!$B$2:$B$20000,$C$4,元データ!$C$2:$C$20000,F$5) -> 988474 | G8: =SUMIFS(INDEX(元データ!$E$2:$H$20000,0,MATCH($C$2,元データ!$E$1:$H$1,0)),元データ!$A$2:$A$20000,$A8,元データ!$D$2:$D$20000,$C$3,元データ!$B$2:$B$20000,$C$4,元データ!$C$2:$C$20000,G$5) -> 945471 | H8: =SUMIFS(INDEX(元データ!$E$2:$H$20000,0,MATCH($C$2,元データ!$E$1:$H$1,0)),元データ!$A$2:$A$20000,$A8,元データ!$D$2:$D$20000,$C$3,元データ!$B$2:$B$20000,$C$4,元データ!$C$2:$C$20000,H$5) -> 567187 | I8: =SUMIFS(INDEX(元データ!$E$2:$H$20000,0,MATCH($C$2,元データ!$E$1:$H$1,0)),元データ!$A$2:$A$20000,$A8,元データ!$D$2:$D$20000,$C$3,元データ!$B$2:$B$20000,$C$4,元データ!$C$2:$C$20000,I$5) -> 564938 | J8: =SUMIFS(INDEX(元データ!$E$2:$H$20000,0,MATCH($C$2,元データ!$E$1:$H$1,0)),元データ!$A$2:$A$20000,$A8,元データ!$D$2:$D$20000,$C$3,元データ!$B$2:$B$20000,$C$4,元データ!$C$2:$C$20000,J$5) -> 1056195 | ... N8: =SUMIFS(INDEX(元データ!$E$2:$H$20000,0,MATCH($C$2,元データ!$E$1:$H$1,0)),元データ!$A$2:$A$20000,$A8,元データ!$D$2:$D$20000,$C$3,元データ!$B$2:$B$20000,$C$4,元データ!$C$2:$C$20000,N$5) -> 0 | O8: =SUM(C8:N8) -> 10631918 | P8: =SUMIFS(INDEX(元データ!$E$2:$H$20000,0,MATCH($C$2,元データ!$E$1:$H$1,0)),元データ!$A$2:$A$20000,$A8,元データ!$D$2:$D$20000,$C$3,元データ!$B$2:$B$20000,$P$4,元データ!$C$2:$C$20000,P$5) -> 764391 | Q8: =SUMIFS(INDEX(元データ!$E$2:$H$20000,0,MATCH($C$2,元データ!$E$1:$H$1,0)),元データ!$A$2:$A$20000,$A8,元データ!$D$2:$D$20000,$C$3,元データ!$B$2:$B$20000,$P$4,元データ!$C$2:$C$20000,Q$5) -> 719935 | R8: =SUMIFS(INDEX(元データ!$E$2:$H$20000,0,MATCH($C$2,元データ!$E$1:$H$1,0)),元データ!$A$2:$A$20000,$A8,元データ!$D$2:$D$20000,$C$3,元データ!$B$2:$B$20000,$P$4,元データ!$C$2:$C$20000,R$5) -> 1166383 | S8: =SUMIFS(INDEX(元データ!$E$2:$H$20000,0,MATCH($C$2,元データ!$E$1:$H$1,0)),元データ!$A$2:$A$20000,$A8,元データ!$D$2:$D$20000,$C$3,元データ!$B$2:$B$20000,$P$4,元データ!$C$2:$C$20000,S$5) -> 961446 | T8: =SUMIFS(INDEX(元データ!$E$2:$H$20000,0,MATCH($C$2,元データ!$E$1:$H$1,0)),元データ!$A$2:$A$20000,$A8,元データ!$D$2:$D$20000,$C$3,元データ!$B$2:$B$20000,$P$4,元データ!$C$2:$C$20000,T$5) -> 1027404 | U8: =SUMIFS(INDEX(元データ!$E$2:$H$20000,0,MATCH($C$2,元データ!$E$1:$H$1,0)),元データ!$A$2:$A$20000,$A8,元データ!$D$2:$D$20000,$C$3,元データ!$B$2:$B$20000,$P$4,元データ!$C$2:$C$20000,U$5) -> 733675 | V8: =SUMIFS(INDEX(元データ!$E$2:$H$20000,0,MATCH($C$2,元データ!$E$1:$H$1,0)),元データ!$A$2:$A$20000,$A8,元データ!$D$2:$D$20000,$C$3,元データ!$B$2:$B$20000,$P$4,元データ!$C$2:$C$20000,V$5) -> 611862 | W8: =SUMIFS(INDEX(元データ!$E$2:$H$20000,0,MATCH($C$2,元データ!$E$1:$H$1,0)),元データ!$A$2:$A$20000,$A8,元データ!$D$2:$D$20000,$C$3,元データ!$B$2:$B$20000,$P$4,元データ!$C$2:$C$20000,W$5) -> 1335104 | ... AA8: =SUMIFS(INDEX(元データ!$E$2:$H$20000,0,MATCH($C$2,元データ!$E$1:$H$1,0)),元データ!$A$2:$A$20000,$A8,元データ!$D$2:$D$20000,$C$3,元データ!$B$2:$B$20000,$P$4,元データ!$C$2:$C$20000,AA$5) -> 0 | AB8: =SUM(P8:AA8) -> 11741841 | AC8: =IFERROR(C8/P8,"") -> 0.9301457 | AD8: =IFERROR(D8/Q8,"") -> 0.98160389 | AE8: =IFERROR(E8/R8,"") -> 0.93069772 | AF8: =IFERROR(F8/S8,"") -> 1.0281118 | AG8: =IFERROR(G8/T8,"") -> 0.9202524 | AH8: =IFERROR(H8/U8,"") -> 0.77307663 | AI8: =IFERROR(I8/V8,"") -> 0.9233095 | AJ8: =IFERROR(J8/W8,"") -> 0.79109567 | ... AO8: =IFERROR(O8/AB8,"") -> 0.90547283
A9: =店舗マスタ!A5 -> 東田中店 | C9: =SUMIFS(INDEX(元データ!$E$2:$H$20000,0,MATCH($C$2,元データ!$E$1:$H$1,0)),元データ!$A$2:$A$20000,$A9,元データ!$D$2:$D$20000,$C$3,元データ!$B$2:$B$20000,$C$4,元データ!$C$2:$C$20000,C$5) -> 1740060 | D9: =SUMIFS(INDEX(元データ!$E$2:$H$20000,0,MATCH($C$2,元データ!$E$1:$H$1,0)),元データ!$A$2:$A$20000,$A9,元データ!$D$2:$D$20000,$C$3,元データ!$B$2:$B$20000,$C$4,元データ!$C$2:$C$20000,D$5) -> 1903597 | E9: =SUMIFS(INDEX(元データ!$E$2:$H$20000,0,MATCH($C$2,元データ!$E$1:$H$1,0)),元データ!$A$2:$A$20000,$A9,元データ!$D$2:$D$20000,$C$3,元データ!$B$2:$B$20000,$C$4,元データ!$C$2:$C$20000,E$5) -> 2817035 | F9: =SUMIFS(INDEX(元データ!$E$2:$H$20000,0,MATCH($C$2,元データ!$E$1:$H$1,0)),元データ!$A$2:$A$20000,$A9,元データ!$D$2:$D$20000,$C$3,元データ!$B$2:$B$20000,$C$4,元データ!$C$2:$C$20000,F$5) -> 2158618 | G9: =SUMIFS(INDEX(元データ!$E$2:$H$20000,0,MATCH($C$2,元データ!$E$1:$H$1,0)),元データ!$A$2:$A$20000,$A9,元データ!$D$2:$D$20000,$C$3,元データ!$B$2:$B$20000,$C$4,元データ!$C$2:$C$20000,G$5) -> 2167750 | H9: =SUMIFS(INDEX(元データ!$E$2:$H$20000,0,MATCH($C$2,元データ!$E$1:$H$1,0)),元データ!$A$2:$A$20000,$A9,元データ!$D$2:$D$20000,$C$3,元データ!$B$2:$B$20000,$C$4,元データ!$C$2:$C$20000,H$5) -> 1428155 | I9: =SUMIFS(INDEX(元データ!$E$2:$H$20000,0,MATCH($C$2,元データ!$E$1:$H$1,0)),元データ!$A$2:$A$20000,$A9,元データ!$D$2:$D$20000,$C$3,元データ!$B$2:$B$20000,$C$4,元データ!$C$2:$C$20000,I$5) -> 1471113 | J9: =SUMIFS(INDEX(元データ!$E$2:$H$20000,0,MATCH($C$2,元データ!$E$1:$H$1,0)),元データ!$A$2:$A$20000,$A9,元データ!$D$2:$D$20000,$C$3,元データ!$B$2:$B$20000,$C$4,元データ!$C$2:$C$20000,J$5) -> 2685111 | ... N9: =SUMIFS(INDEX(元データ!$E$2:$H$20000,0,MATCH($C$2,元データ!$E$1:$H$1,0)),元データ!$A$2:$A$20000,$A9,元データ!$D$2:$D$20000,$C$3,元データ!$B$2:$B$20000,$C$4,元データ!$C$2:$C$20000,N$5) -> 2731393 | O9: =SUM(C9:N9) -> 29678537 | P9: =SUMIFS(INDEX(元データ!$E$2:$H$20000,0,MATCH($C$2,元データ!$E$1:$H$1,0)),元データ!$A$2:$A$20000,$A9,元データ!$D$2:$D$20000,$C$3,元データ!$B$2:$B$20000,$P$4,元データ!$C$2:$C$20000,P$5) -> 1800070 | Q9: =SUMIFS(INDEX(元データ!$E$2:$H$20000,0,MATCH($C$2,元データ!$E$1:$H$1,0)),元データ!$A$2:$A$20000,$A9,元データ!$D$2:$D$20000,$C$3,元データ!$B$2:$B$20000,$P$4,元データ!$C$2:$C$20000,Q$5) -> 1629373 | R9: =SUMIFS(INDEX(元データ!$E$2:$H$20000,0,MATCH($C$2,元データ!$E$1:$H$1,0)),元データ!$A$2:$A$20000,$A9,元データ!$D$2:$D$20000,$C$3,元データ!$B$2:$B$20000,$P$4,元データ!$C$2:$C$20000,R$5) -> 2464702 | S9: =SUMIFS(INDEX(元データ!$E$2:$H$20000,0,MATCH($C$2,元データ!$E$1:$H$1,0)),元データ!$A$2:$A$20000,$A9,元データ!$D$2:$D$20000,$C$3,元データ!$B$2:$B$20000,$P$4,元データ!$C$2:$C$20000,S$5) -> 2149893 | T9: =SUMIFS(INDEX(元データ!$E$2:$H$20000,0,MATCH($C$2,元データ!$E$1:$H$1,0)),元データ!$A$2:$A$20000,$A9,元データ!$D$2:$D$20000,$C$3,元データ!$B$2:$B$20000,$P$4,元データ!$C$2:$C$20000,T$5) -> 2174894 | U9: =SUMIFS(INDEX(元データ!$E$2:$H$20000,0,MATCH($C$2,元データ!$E$1:$H$1,0)),元データ!$A$2:$A$20000,$A9,元データ!$D$2:$D$20000,$C$3,元データ!$B$2:$B$20000,$P$4,元データ!$C$2:$C$20000,U$5) -> 1454711 | V9: =SUMIFS(INDEX(元データ!$E$2:$H$20000,0,MATCH($C$2,元データ!$E$1:$H$1,0)),元データ!$A$2:$A$20000,$A9,元データ!$D$2:$D$20000,$C$3,元データ!$B$2:$B$20000,$P$4,元データ!$C$2:$C$20000,V$5) -> 1335533 | W9: =SUMIFS(INDEX(元データ!$E$2:$H$20000,0,MATCH($C$2,元データ!$E$1:$H$1,0)),元データ!$A$2:$A$20000,$A9,元データ!$D$2:$D$20000,$C$3,元データ!$B$2:$B$20000,$P$4,元データ!$C$2:$C$20000,W$5) -> 3050456 | ... AA9: =SUMIFS(INDEX(元データ!$E$2:$H$20000,0,MATCH($C$2,元データ!$E$1:$H$1,0)),元データ!$A$2:$A$20000,$A9,元データ!$D$2:$D$20000,$C$3,元データ!$B$2:$B$20000,$P$4,元データ!$C$2:$C$20000,AA$5) -> 2301129 | AB9: =SUM(P9:AA9) -> 29011272 | AC9: =IFERROR(C9/P9,"") -> 0.96666241 | AD9: =IFERROR(D9/Q9,"") -> 1.1683003 | AE9: =IFERROR(E9/R9,"") -> 1.1429516 | AF9: =IFERROR(F9/S9,"") -> 1.0040583 | AG9: =IFERROR(G9/T9,"") -> 0.99671524 | AH9: =IFERROR(H9/U9,"") -> 0.98174483 | AI9: =IFERROR(I9/V9,"") -> 1.1015175 | AJ9: =IFERROR(J9/W9,"") -> 0.88023266 | ... AO9: =IFERROR(O9/AB9,"") -> 1.0230002
A10: =店舗マスタ!A6 -> 桜堤店 | C10: =SUMIFS(INDEX(元データ!$E$2:$H$20000,0,MATCH($C$2,元データ!$E$1:$H$1,0)),元データ!$A$2:$A$20000,$A10,元データ!$D$2:$D$20000,$C$3,元データ!$B$2:$B$20000,$C$4,元データ!$C$2:$C$20000,C$5) -> 1098993 | D10: =SUMIFS(INDEX(元データ!$E$2:$H$20000,0,MATCH($C$2,元データ!$E$1:$H$1,0)),元データ!$A$2:$A$20000,$A10,元データ!$D$2:$D$20000,$C$3,元データ!$B$2:$B$20000,$C$4,元データ!$C$2:$C$20000,D$5) -> 1121103 | E10: =SUMIFS(INDEX(元データ!$E$2:$H$20000,0,MATCH($C$2,元データ!$E$1:$H$1,0)),元データ!$A$2:$A$20000,$A10,元データ!$D$2:$D$20000,$C$3,元データ!$B$2:$B$20000,$C$4,元データ!$C$2:$C$20000,E$5) -> 1544784 | F10: =SUMIFS(INDEX(元データ!$E$2:$H$20000,0,MATCH($C$2,元データ!$E$1:$H$1,0)),元データ!$A$2:$A$20000,$A10,元データ!$D$2:$D$20000,$C$3,元データ!$B$2:$B$20000,$C$4,元データ!$C$2:$C$20000,F$5) -> 1415062 | G10: =SUMIFS(INDEX(元データ!$E$2:$H$20000,0,MATCH($C$2,元データ!$E$1:$H$1,0)),元データ!$A$2:$A$20000,$A10,元データ!$D$2:$D$20000,$C$3,元データ!$B$2:$B$20000,$C$4,元データ!$C$2:$C$20000,G$5) -> 1579598 | H10: =SUMIFS(INDEX(元データ!$E$2:$H$20000,0,MATCH($C$2,元データ!$E$1:$H$1,0)),元データ!$A$2:$A$20000,$A10,元データ!$D$2:$D$20000,$C$3,元データ!$B$2:$B$20000,$C$4,元データ!$C$2:$C$20000,H$5) -> 1079345 | I10: =SUMIFS(INDEX(元データ!$E$2:$H$20000,0,MATCH($C$2,元データ!$E$1:$H$1,0)),元データ!$A$2:$A$20000,$A10,元データ!$D$2:$D$20000,$C$3,元データ!$B$2:$B$20000,$C$4,元データ!$C$2:$C$20000,I$5) -> 1059155 | J10: =SUMIFS(INDEX(元データ!$E$2:$H$20000,0,MATCH($C$2,元データ!$E$1:$H$1,0)),元データ!$A$2:$A$20000,$A10,元データ!$D$2:$D$20000,$C$3,元データ!$B$2:$B$20000,$C$4,元データ!$C$2:$C$20000,J$5) -> 2088429 | ... N10: =SUMIFS(INDEX(元データ!$E$2:$H$20000,0,MATCH($C$2,元データ!$E$1:$H$1,0)),元データ!$A$2:$A$20000,$A10,元データ!$D$2:$D$20000,$C$3,元データ!$B$2:$B$20000,$C$4,元データ!$C$2:$C$20000,N$5) -> 1589927 | O10: =SUM(C10:N10) -> 20720634 | P10: =SUMIFS(INDEX(元データ!$E$2:$H$20000,0,MATCH($C$2,元データ!$E$1:$H$1,0)),元データ!$A$2:$A$20000,$A10,元データ!$D$2:$D$20000,$C$3,元データ!$B$2:$B$20000,$P$4,元データ!$C$2:$C$20000,P$5) -> 1011666 | Q10: =SUMIFS(INDEX(元データ!$E$2:$H$20000,0,MATCH($C$2,元データ!$E$1:$H$1,0)),元データ!$A$2:$A$20000,$A10,元データ!$D$2:$D$20000,$C$3,元データ!$B$2:$B$20000,$P$4,元データ!$C$2:$C$20000,Q$5) -> 1084473 | R10: =SUMIFS(INDEX(元データ!$E$2:$H$20000,0,MATCH($C$2,元データ!$E$1:$H$1,0)),元データ!$A$2:$A$20000,$A10,元データ!$D$2:$D$20000,$C$3,元データ!$B$2:$B$20000,$P$4,元データ!$C$2:$C$20000,R$5) -> 1746860 | S10: =SUMIFS(INDEX(元データ!$E$2:$H$20000,0,MATCH($C$2,元データ!$E$1:$H$1,0)),元データ!$A$2:$A$20000,$A10,元データ!$D$2:$D$20000,$C$3,元データ!$B$2:$B$20000,$P$4,元データ!$C$2:$C$20000,S$5) -> 1283244 | T10: =SUMIFS(INDEX(元データ!$E$2:$H$20000,0,MATCH($C$2,元データ!$E$1:$H$1,0)),元データ!$A$2:$A$20000,$A10,元データ!$D$2:$D$20000,$C$3,元データ!$B$2:$B$20000,$P$4,元データ!$C$2:$C$20000,T$5) -> 1546516 | U10: =SUMIFS(INDEX(元データ!$E$2:$H$20000,0,MATCH($C$2,元データ!$E$1:$H$1,0)),元データ!$A$2:$A$20000,$A10,元データ!$D$2:$D$20000,$C$3,元データ!$B$2:$B$20000,$P$4,元データ!$C$2:$C$20000,U$5) -> 1047121 | V10: =SUMIFS(INDEX(元データ!$E$2:$H$20000,0,MATCH($C$2,元データ!$E$1:$H$1,0)),元データ!$A$2:$A$20000,$A10,元データ!$D$2:$D$20000,$C$3,元データ!$B$2:$B$20000,$P$4,元データ!$C$2:$C$20000,V$5) -> 836571 | W10: =SUMIFS(INDEX(元データ!$E$2:$H$20000,0,MATCH($C$2,元データ!$E$1:$H$1,0)),元データ!$A$2:$A$20000,$A10,元データ!$D$2:$D$20000,$C$3,元データ!$B$2:$B$20000,$P$4,元データ!$C$2:$C$20000,W$5) -> 2230220 | ... AA10: =SUMIFS(INDEX(元データ!$E$2:$H$20000,0,MATCH($C$2,元データ!$E$1:$H$1,0)),元データ!$A$2:$A$20000,$A10,元データ!$D$2:$D$20000,$C$3,元データ!$B$2:$B$20000,$P$4,元データ!$C$2:$C$20000,AA$5) -> 2509100 | AB10: =SUM(P10:AA10) -> 21369896 | AC10: =IFERROR(C10/P10,"") -> 1.08632 | AD10: =IFERROR(D10/Q10,"") -> 1.0337768 | AE10: =IFERROR(E10/R10,"") -> 0.88432044 | AF10: =IFERROR(F10/S10,"") -> 1.1027225 | AG10: =IFERROR(G10/T10,"") -> 1.0213913 | AH10: =IFERROR(H10/U10,"") -> 1.0307739 | AI10: =IFERROR(I10/V10,"") -> 1.2660671 | AJ10: =IFERROR(J10/W10,"") -> 0.93642286 | ... AO10: =IFERROR(O10/AB10,"") -> 0.96961791
A11: =店舗マスタ!A7 -> 香貫店 | C11: =SUMIFS(INDEX(元データ!$E$2:$H$20000,0,MATCH($C$2,元データ!$E$1:$H$1,0)),元データ!$A$2:$A$20000,$A11,元データ!$D$2:$D$20000,$C$3,元データ!$B$2:$B$20000,$C$4,元データ!$C$2:$C$20000,C$5) -> 1413894 | D11: =SUMIFS(INDEX(元データ!$E$2:$H$20000,0,MATCH($C$2,元データ!$E$1:$H$1,0)),元データ!$A$2:$A$20000,$A11,元データ!$D$2:$D$20000,$C$3,元データ!$B$2:$B$20000,$C$4,元データ!$C$2:$C$20000,D$5) -> 1250107 | E11: =SUMIFS(INDEX(元データ!$E$2:$H$20000,0,MATCH($C$2,元データ!$E$1:$H$1,0)),元データ!$A$2:$A$20000,$A11,元データ!$D$2:$D$20000,$C$3,元データ!$B$2:$B$20000,$C$4,元データ!$C$2:$C$20000,E$5) -> 1814455 | F11: =SUMIFS(INDEX(元データ!$E$2:$H$20000,0,MATCH($C$2,元データ!$E$1:$H$1,0)),元データ!$A$2:$A$20000,$A11,元データ!$D$2:$D$20000,$C$3,元データ!$B$2:$B$20000,$C$4,元データ!$C$2:$C$20000,F$5) -> 1794355 | G11: =SUMIFS(INDEX(元データ!$E$2:$H$20000,0,MATCH($C$2,元データ!$E$1:$H$1,0)),元データ!$A$2:$A$20000,$A11,元データ!$D$2:$D$20000,$C$3,元データ!$B$2:$B$20000,$C$4,元データ!$C$2:$C$20000,G$5) -> 1716904 | H11: =SUMIFS(INDEX(元データ!$E$2:$H$20000,0,MATCH($C$2,元データ!$E$1:$H$1,0)),元データ!$A$2:$A$20000,$A11,元データ!$D$2:$D$20000,$C$3,元データ!$B$2:$B$20000,$C$4,元データ!$C$2:$C$20000,H$5) -> 1227030 | I11: =SUMIFS(INDEX(元データ!$E$2:$H$20000,0,MATCH($C$2,元データ!$E$1:$H$1,0)),元データ!$A$2:$A$20000,$A11,元データ!$D$2:$D$20000,$C$3,元データ!$B$2:$B$20000,$C$4,元データ!$C$2:$C$20000,I$5) -> 1004975 | J11: =SUMIFS(INDEX(元データ!$E$2:$H$20000,0,MATCH($C$2,元データ!$E$1:$H$1,0)),元データ!$A$2:$A$20000,$A11,元データ!$D$2:$D$20000,$C$3,元データ!$B$2:$B$20000,$C$4,元データ!$C$2:$C$20000,J$5) -> 1817093 | ... N11: =SUMIFS(INDEX(元データ!$E$2:$H$20000,0,MATCH($C$2,元データ!$E$1:$H$1,0)),元データ!$A$2:$A$20000,$A11,元データ!$D$2:$D$20000,$C$3,元データ!$B$2:$B$20000,$C$4,元データ!$C$2:$C$20000,N$5) -> 2220375 | O11: =SUM(C11:N11) -> 22165952 | P11: =SUMIFS(INDEX(元データ!$E$2:$H$20000,0,MATCH($C$2,元データ!$E$1:$H$1,0)),元データ!$A$2:$A$20000,$A11,元データ!$D$2:$D$20000,$C$3,元データ!$B$2:$B$20000,$P$4,元データ!$C$2:$C$20000,P$5) -> 1186553 | Q11: =SUMIFS(INDEX(元データ!$E$2:$H$20000,0,MATCH($C$2,元データ!$E$1:$H$1,0)),元データ!$A$2:$A$20000,$A11,元データ!$D$2:$D$20000,$C$3,元データ!$B$2:$B$20000,$P$4,元データ!$C$2:$C$20000,Q$5) -> 1121191 | R11: =SUMIFS(INDEX(元データ!$E$2:$H$20000,0,MATCH($C$2,元データ!$E$1:$H$1,0)),元データ!$A$2:$A$20000,$A11,元データ!$D$2:$D$20000,$C$3,元データ!$B$2:$B$20000,$P$4,元データ!$C$2:$C$20000,R$5) -> 1928810 | S11: =SUMIFS(INDEX(元データ!$E$2:$H$20000,0,MATCH($C$2,元データ!$E$1:$H$1,0)),元データ!$A$2:$A$20000,$A11,元データ!$D$2:$D$20000,$C$3,元データ!$B$2:$B$20000,$P$4,元データ!$C$2:$C$20000,S$5) -> 1609527 | T11: =SUMIFS(INDEX(元データ!$E$2:$H$20000,0,MATCH($C$2,元データ!$E$1:$H$1,0)),元データ!$A$2:$A$20000,$A11,元データ!$D$2:$D$20000,$C$3,元データ!$B$2:$B$20000,$P$4,元データ!$C$2:$C$20000,T$5) -> 1649775 | U11: =SUMIFS(INDEX(元データ!$E$2:$H$20000,0,MATCH($C$2,元データ!$E$1:$H$1,0)),元データ!$A$2:$A$20000,$A11,元データ!$D$2:$D$20000,$C$3,元データ!$B$2:$B$20000,$P$4,元データ!$C$2:$C$20000,U$5) -> 1150922 | V11: =SUMIFS(INDEX(元データ!$E$2:$H$20000,0,MATCH($C$2,元データ!$E$1:$H$1,0)),元データ!$A$2:$A$20000,$A11,元データ!$D$2:$D$20000,$C$3,元データ!$B$2:$B$20000,$P$4,元データ!$C$2:$C$20000,V$5) -> 1142407 | W11: =SUMIFS(INDEX(元データ!$E$2:$H$20000,0,MATCH($C$2,元データ!$E$1:$H$1,0)),元データ!$A$2:$A$20000,$A11,元データ!$D$2:$D$20000,$C$3,元データ!$B$2:$B$20000,$P$4,元データ!$C$2:$C$20000,W$5) -> 2333385 | ... AA11: =SUMIFS(INDEX(元データ!$E$2:$H$20000,0,MATCH($C$2,元データ!$E$1:$H$1,0)),元データ!$A$2:$A$20000,$A11,元データ!$D$2:$D$20000,$C$3,元データ!$B$2:$B$20000,$P$4,元データ!$C$2:$C$20000,AA$5) -> 1610531 | AB11: =SUM(P11:AA11) -> 21519845 | AC11: =IFERROR(C11/P11,"") -> 1.1915978 | AD11: =IFERROR(D11/Q11,"") -> 1.1149813 | AE11: =IFERROR(E11/R11,"") -> 0.94071215 | AF11: =IFERROR(F11/S11,"") -> 1.1148337 | AG11: =IFERROR(G11/T11,"") -> 1.0406898 | AH11: =IFERROR(H11/U11,"") -> 1.0661279 | AI11: =IFERROR(I11/V11,"") -> 0.87969962 | AJ11: =IFERROR(J11/W11,"") -> 0.7787369 | ... AO11: =IFERROR(O11/AB11,"") -> 1.0300238
A12: =店舗マスタ!A8 -> 学園通り店 | C12: =SUMIFS(INDEX(元データ!$E$2:$H$20000,0,MATCH($C$2,元データ!$E$1:$H$1,0)),元データ!$A$2:$A$20000,$A12,元データ!$D$2:$D$20000,$C$3,元データ!$B$2:$B$20000,$C$4,元データ!$C$2:$C$20000,C$5) -> 1480843 | D12: =SUMIFS(INDEX(元データ!$E$2:$H$20000,0,MATCH($C$2,元データ!$E$1:$H$1,0)),元データ!$A$2:$A$20000,$A12,元データ!$D$2:$D$20000,$C$3,元データ!$B$2:$B$20000,$C$4,元データ!$C$2:$C$20000,D$5) -> 1395472 | E12: =SUMIFS(INDEX(元データ!$E$2:$H$20000,0,MATCH($C$2,元データ!$E$1:$H$1,0)),元データ!$A$2:$A$20000,$A12,元データ!$D$2:$D$20000,$C$3,元データ!$B$2:$B$20000,$C$4,元データ!$C$2:$C$20000,E$5) -> 1991330 | F12: =SUMIFS(INDEX(元データ!$E$2:$H$20000,0,MATCH($C$2,元データ!$E$1:$H$1,0)),元データ!$A$2:$A$20000,$A12,元データ!$D$2:$D$20000,$C$3,元データ!$B$2:$B$20000,$C$4,元データ!$C$2:$C$20000,F$5) -> 1960427 | G12: =SUMIFS(INDEX(元データ!$E$2:$H$20000,0,MATCH($C$2,元データ!$E$1:$H$1,0)),元データ!$A$2:$A$20000,$A12,元データ!$D$2:$D$20000,$C$3,元データ!$B$2:$B$20000,$C$4,元データ!$C$2:$C$20000,G$5) -> 2003125 | H12: =SUMIFS(INDEX(元データ!$E$2:$H$20000,0,MATCH($C$2,元データ!$E$1:$H$1,0)),元データ!$A$2:$A$20000,$A12,元データ!$D$2:$D$20000,$C$3,元データ!$B$2:$B$20000,$C$4,元データ!$C$2:$C$20000,H$5) -> 1369602 | I12: =SUMIFS(INDEX(元データ!$E$2:$H$20000,0,MATCH($C$2,元データ!$E$1:$H$1,0)),元データ!$A$2:$A$20000,$A12,元データ!$D$2:$D$20000,$C$3,元データ!$B$2:$B$20000,$C$4,元データ!$C$2:$C$20000,I$5) -> 1378807 | J12: =SUMIFS(INDEX(元データ!$E$2:$H$20000,0,MATCH($C$2,元データ!$E$1:$H$1,0)),元データ!$A$2:$A$20000,$A12,元データ!$D$2:$D$20000,$C$3,元データ!$B$2:$B$20000,$C$4,元データ!$C$2:$C$20000,J$5) -> 2101540 | ... N12: =SUMIFS(INDEX(元データ!$E$2:$H$20000,0,MATCH($C$2,元データ!$E$1:$H$1,0)),元データ!$A$2:$A$20000,$A12,元データ!$D$2:$D$20000,$C$3,元データ!$B$2:$B$20000,$C$4,元データ!$C$2:$C$20000,N$5) -> 1697291 | O12: =SUM(C12:N12) -> 23811257 | P12: =SUMIFS(INDEX(元データ!$E$2:$H$20000,0,MATCH($C$2,元データ!$E$1:$H$1,0)),元データ!$A$2:$A$20000,$A12,元データ!$D$2:$D$20000,$C$3,元データ!$B$2:$B$20000,$P$4,元データ!$C$2:$C$20000,P$5) -> 1556088 | Q12: =SUMIFS(INDEX(元データ!$E$2:$H$20000,0,MATCH($C$2,元データ!$E$1:$H$1,0)),元データ!$A$2:$A$20000,$A12,元データ!$D$2:$D$20000,$C$3,元データ!$B$2:$B$20000,$P$4,元データ!$C$2:$C$20000,Q$5) -> 1302395 | R12: =SUMIFS(INDEX(元データ!$E$2:$H$20000,0,MATCH($C$2,元データ!$E$1:$H$1,0)),元データ!$A$2:$A$20000,$A12,元データ!$D$2:$D$20000,$C$3,元データ!$B$2:$B$20000,$P$4,元データ!$C$2:$C$20000,R$5) -> 2091313 | S12: =SUMIFS(INDEX(元データ!$E$2:$H$20000,0,MATCH($C$2,元データ!$E$1:$H$1,0)),元データ!$A$2:$A$20000,$A12,元データ!$D$2:$D$20000,$C$3,元データ!$B$2:$B$20000,$P$4,元データ!$C$2:$C$20000,S$5) -> 1728666 | T12: =SUMIFS(INDEX(元データ!$E$2:$H$20000,0,MATCH($C$2,元データ!$E$1:$H$1,0)),元データ!$A$2:$A$20000,$A12,元データ!$D$2:$D$20000,$C$3,元データ!$B$2:$B$20000,$P$4,元データ!$C$2:$C$20000,T$5) -> 1740174 | U12: =SUMIFS(INDEX(元データ!$E$2:$H$20000,0,MATCH($C$2,元データ!$E$1:$H$1,0)),元データ!$A$2:$A$20000,$A12,元データ!$D$2:$D$20000,$C$3,元データ!$B$2:$B$20000,$P$4,元データ!$C$2:$C$20000,U$5) -> 1186756 | V12: =SUMIFS(INDEX(元データ!$E$2:$H$20000,0,MATCH($C$2,元データ!$E$1:$H$1,0)),元データ!$A$2:$A$20000,$A12,元データ!$D$2:$D$20000,$C$3,元データ!$B$2:$B$20000,$P$4,元データ!$C$2:$C$20000,V$5) -> 1179738 | W12: =SUMIFS(INDEX(元データ!$E$2:$H$20000,0,MATCH($C$2,元データ!$E$1:$H$1,0)),元データ!$A$2:$A$20000,$A12,元データ!$D$2:$D$20000,$C$3,元データ!$B$2:$B$20000,$P$4,元データ!$C$2:$C$20000,W$5) -> 2572529 | ... AA12: =SUMIFS(INDEX(元データ!$E$2:$H$20000,0,MATCH($C$2,元データ!$E$1:$H$1,0)),元データ!$A$2:$A$20000,$A12,元データ!$D$2:$D$20000,$C$3,元データ!$B$2:$B$20000,$P$4,元データ!$C$2:$C$20000,AA$5) -> 1657353 | AB12: =SUM(P12:AA12) -> 23736088 | AC12: =IFERROR(C12/P12,"") -> 0.95164477 | AD12: =IFERROR(D12/Q12,"") -> 1.071466 | AE12: =IFERROR(E12/R12,"") -> 0.95219128 | AF12: =IFERROR(F12/S12,"") -> 1.1340693 | AG12: =IFERROR(G12/T12,"") -> 1.1511062 | AH12: =IFERROR(H12/U12,"") -> 1.1540721 | AI12: =IFERROR(I12/V12,"") -> 1.16874 | AJ12: =IFERROR(J12/W12,"") -> 0.81691596 | ... AO12: =IFERROR(O12/AB12,"") -> 1.0031669
A13: =店舗マスタ!A9 -> 伏見店 | C13: =SUMIFS(INDEX(元データ!$E$2:$H$20000,0,MATCH($C$2,元データ!$E$1:$H$1,0)),元データ!$A$2:$A$20000,$A13,元データ!$D$2:$D$20000,$C$3,元データ!$B$2:$B$20000,$C$4,元データ!$C$2:$C$20000,C$5) -> 713186 | D13: =SUMIFS(INDEX(元データ!$E$2:$H$20000,0,MATCH($C$2,元データ!$E$1:$H$1,0)),元データ!$A$2:$A$20000,$A13,元データ!$D$2:$D$20000,$C$3,元データ!$B$2:$B$20000,$C$4,元データ!$C$2:$C$20000,D$5) -> 748920 | E13: =SUMIFS(INDEX(元データ!$E$2:$H$20000,0,MATCH($C$2,元データ!$E$1:$H$1,0)),元データ!$A$2:$A$20000,$A13,元データ!$D$2:$D$20000,$C$3,元データ!$B$2:$B$20000,$C$4,元データ!$C$2:$C$20000,E$5) -> 1031058 | F13: =SUMIFS(INDEX(元データ!$E$2:$H$20000,0,MATCH($C$2,元データ!$E$1:$H$1,0)),元データ!$A$2:$A$20000,$A13,元データ!$D$2:$D$20000,$C$3,元データ!$B$2:$B$20000,$C$4,元データ!$C$2:$C$20000,F$5) -> 855276 | G13: =SUMIFS(INDEX(元データ!$E$2:$H$20000,0,MATCH($C$2,元データ!$E$1:$H$1,0)),元データ!$A$2:$A$20000,$A13,元データ!$D$2:$D$20000,$C$3,元データ!$B$2:$B$20000,$C$4,元データ!$C$2:$C$20000,G$5) -> 926945 | H13: =SUMIFS(INDEX(元データ!$E$2:$H$20000,0,MATCH($C$2,元データ!$E$1:$H$1,0)),元データ!$A$2:$A$20000,$A13,元データ!$D$2:$D$20000,$C$3,元データ!$B$2:$B$20000,$C$4,元データ!$C$2:$C$20000,H$5) -> 654195 | I13: =SUMIFS(INDEX(元データ!$E$2:$H$20000,0,MATCH($C$2,元データ!$E$1:$H$1,0)),元データ!$A$2:$A$20000,$A13,元データ!$D$2:$D$20000,$C$3,元データ!$B$2:$B$20000,$C$4,元データ!$C$2:$C$20000,I$5) -> 621110 | J13: =SUMIFS(INDEX(元データ!$E$2:$H$20000,0,MATCH($C$2,元データ!$E$1:$H$1,0)),元データ!$A$2:$A$20000,$A13,元データ!$D$2:$D$20000,$C$3,元データ!$B$2:$B$20000,$C$4,元データ!$C$2:$C$20000,J$5) -> 1196174 | ... N13: =SUMIFS(INDEX(元データ!$E$2:$H$20000,0,MATCH($C$2,元データ!$E$1:$H$1,0)),元データ!$A$2:$A$20000,$A13,元データ!$D$2:$D$20000,$C$3,元データ!$B$2:$B$20000,$C$4,元データ!$C$2:$C$20000,N$5) -> 0 | O13: =SUM(C13:N13) -> 10106931 | P13: =SUMIFS(INDEX(元データ!$E$2:$H$20000,0,MATCH($C$2,元データ!$E$1:$H$1,0)),元データ!$A$2:$A$20000,$A13,元データ!$D$2:$D$20000,$C$3,元データ!$B$2:$B$20000,$P$4,元データ!$C$2:$C$20000,P$5) -> 774827 | Q13: =SUMIFS(INDEX(元データ!$E$2:$H$20000,0,MATCH($C$2,元データ!$E$1:$H$1,0)),元データ!$A$2:$A$20000,$A13,元データ!$D$2:$D$20000,$C$3,元データ!$B$2:$B$20000,$P$4,元データ!$C$2:$C$20000,Q$5) -> 651160 | R13: =SUMIFS(INDEX(元データ!$E$2:$H$20000,0,MATCH($C$2,元データ!$E$1:$H$1,0)),元データ!$A$2:$A$20000,$A13,元データ!$D$2:$D$20000,$C$3,元データ!$B$2:$B$20000,$P$4,元データ!$C$2:$C$20000,R$5) -> 1101147 | S13: =SUMIFS(INDEX(元データ!$E$2:$H$20000,0,MATCH($C$2,元データ!$E$1:$H$1,0)),元データ!$A$2:$A$20000,$A13,元データ!$D$2:$D$20000,$C$3,元データ!$B$2:$B$20000,$P$4,元データ!$C$2:$C$20000,S$5) -> 880574 | T13: =SUMIFS(INDEX(元データ!$E$2:$H$20000,0,MATCH($C$2,元データ!$E$1:$H$1,0)),元データ!$A$2:$A$20000,$A13,元データ!$D$2:$D$20000,$C$3,元データ!$B$2:$B$20000,$P$4,元データ!$C$2:$C$20000,T$5) -> 952961 | U13: =SUMIFS(INDEX(元データ!$E$2:$H$20000,0,MATCH($C$2,元データ!$E$1:$H$1,0)),元データ!$A$2:$A$20000,$A13,元データ!$D$2:$D$20000,$C$3,元データ!$B$2:$B$20000,$P$4,元データ!$C$2:$C$20000,U$5) -> 641546 | V13: =SUMIFS(INDEX(元データ!$E$2:$H$20000,0,MATCH($C$2,元データ!$E$1:$H$1,0)),元データ!$A$2:$A$20000,$A13,元データ!$D$2:$D$20000,$C$3,元データ!$B$2:$B$20000,$P$4,元データ!$C$2:$C$20000,V$5) -> 600487 | W13: =SUMIFS(INDEX(元データ!$E$2:$H$20000,0,MATCH($C$2,元データ!$E$1:$H$1,0)),元データ!$A$2:$A$20000,$A13,元データ!$D$2:$D$20000,$C$3,元データ!$B$2:$B$20000,$P$4,元データ!$C$2:$C$20000,W$5) -> 1366007 | ... AA13: =SUMIFS(INDEX(元データ!$E$2:$H$20000,0,MATCH($C$2,元データ!$E$1:$H$1,0)),元データ!$A$2:$A$20000,$A13,元データ!$D$2:$D$20000,$C$3,元データ!$B$2:$B$20000,$P$4,元データ!$C$2:$C$20000,AA$5) -> 0 | AB13: =SUM(P13:AA13) -> 10295621 | AC13: =IFERROR(C13/P13,"") -> 0.92044547 | AD13: =IFERROR(D13/Q13,"") -> 1.1501321 | AE13: =IFERROR(E13/R13,"") -> 0.9363491 | AF13: =IFERROR(F13/S13,"") -> 0.97127101 | AG13: =IFERROR(G13/T13,"") -> 0.97269983 | AH13: =IFERROR(H13/U13,"") -> 1.0197164 | AI13: =IFERROR(I13/V13,"") -> 1.0343438 | AJ13: =IFERROR(J13/W13,"") -> 0.87567194 | ... AO13: =IFERROR(O13/AB13,"") -> 0.98167279
A14: =店舗マスタ!A10 -> 原里店 | C14: =SUMIFS(INDEX(元データ!$E$2:$H$20000,0,MATCH($C$2,元データ!$E$1:$H$1,0)),元データ!$A$2:$A$20000,$A14,元データ!$D$2:$D$20000,$C$3,元データ!$B$2:$B$20000,$C$4,元データ!$C$2:$C$20000,C$5) -> 1243436 | D14: =SUMIFS(INDEX(元データ!$E$2:$H$20000,0,MATCH($C$2,元データ!$E$1:$H$1,0)),元データ!$A$2:$A$20000,$A14,元データ!$D$2:$D$20000,$C$3,元データ!$B$2:$B$20000,$C$4,元データ!$C$2:$C$20000,D$5) -> 1250265 | E14: =SUMIFS(INDEX(元データ!$E$2:$H$20000,0,MATCH($C$2,元データ!$E$1:$H$1,0)),元データ!$A$2:$A$20000,$A14,元データ!$D$2:$D$20000,$C$3,元データ!$B$2:$B$20000,$C$4,元データ!$C$2:$C$20000,E$5) -> 1728575 | F14: =SUMIFS(INDEX(元データ!$E$2:$H$20000,0,MATCH($C$2,元データ!$E$1:$H$1,0)),元データ!$A$2:$A$20000,$A14,元データ!$D$2:$D$20000,$C$3,元データ!$B$2:$B$20000,$C$4,元データ!$C$2:$C$20000,F$5) -> 1170503 | G14: =SUMIFS(INDEX(元データ!$E$2:$H$20000,0,MATCH($C$2,元データ!$E$1:$H$1,0)),元データ!$A$2:$A$20000,$A14,元データ!$D$2:$D$20000,$C$3,元データ!$B$2:$B$20000,$C$4,元データ!$C$2:$C$20000,G$5) -> 1331350 | H14: =SUMIFS(INDEX(元データ!$E$2:$H$20000,0,MATCH($C$2,元データ!$E$1:$H$1,0)),元データ!$A$2:$A$20000,$A14,元データ!$D$2:$D$20000,$C$3,元データ!$B$2:$B$20000,$C$4,元データ!$C$2:$C$20000,H$5) -> 1101408 | I14: =SUMIFS(INDEX(元データ!$E$2:$H$20000,0,MATCH($C$2,元データ!$E$1:$H$1,0)),元データ!$A$2:$A$20000,$A14,元データ!$D$2:$D$20000,$C$3,元データ!$B$2:$B$20000,$C$4,元データ!$C$2:$C$20000,I$5) -> 1003947 | J14: =SUMIFS(INDEX(元データ!$E$2:$H$20000,0,MATCH($C$2,元データ!$E$1:$H$1,0)),元データ!$A$2:$A$20000,$A14,元データ!$D$2:$D$20000,$C$3,元データ!$B$2:$B$20000,$C$4,元データ!$C$2:$C$20000,J$5) -> 1604434 | ... N14: =SUMIFS(INDEX(元データ!$E$2:$H$20000,0,MATCH($C$2,元データ!$E$1:$H$1,0)),元データ!$A$2:$A$20000,$A14,元データ!$D$2:$D$20000,$C$3,元データ!$B$2:$B$20000,$C$4,元データ!$C$2:$C$20000,N$5) -> 1848514 | O14: =SUM(C14:N14) -> 18153089 | P14: =SUMIFS(INDEX(元データ!$E$2:$H$20000,0,MATCH($C$2,元データ!$E$1:$H$1,0)),元データ!$A$2:$A$20000,$A14,元データ!$D$2:$D$20000,$C$3,元データ!$B$2:$B$20000,$P$4,元データ!$C$2:$C$20000,P$5) -> 1241919 | Q14: =SUMIFS(INDEX(元データ!$E$2:$H$20000,0,MATCH($C$2,元データ!$E$1:$H$1,0)),元データ!$A$2:$A$20000,$A14,元データ!$D$2:$D$20000,$C$3,元データ!$B$2:$B$20000,$P$4,元データ!$C$2:$C$20000,Q$5) -> 1121488 | R14: =SUMIFS(INDEX(元データ!$E$2:$H$20000,0,MATCH($C$2,元データ!$E$1:$H$1,0)),元データ!$A$2:$A$20000,$A14,元データ!$D$2:$D$20000,$C$3,元データ!$B$2:$B$20000,$P$4,元データ!$C$2:$C$20000,R$5) -> 1622400 | S14: =SUMIFS(INDEX(元データ!$E$2:$H$20000,0,MATCH($C$2,元データ!$E$1:$H$1,0)),元データ!$A$2:$A$20000,$A14,元データ!$D$2:$D$20000,$C$3,元データ!$B$2:$B$20000,$P$4,元データ!$C$2:$C$20000,S$5) -> 1283231 | T14: =SUMIFS(INDEX(元データ!$E$2:$H$20000,0,MATCH($C$2,元データ!$E$1:$H$1,0)),元データ!$A$2:$A$20000,$A14,元データ!$D$2:$D$20000,$C$3,元データ!$B$2:$B$20000,$P$4,元データ!$C$2:$C$20000,T$5) -> 1331220 | U14: =SUMIFS(INDEX(元データ!$E$2:$H$20000,0,MATCH($C$2,元データ!$E$1:$H$1,0)),元データ!$A$2:$A$20000,$A14,元データ!$D$2:$D$20000,$C$3,元データ!$B$2:$B$20000,$P$4,元データ!$C$2:$C$20000,U$5) -> 1019920 | V14: =SUMIFS(INDEX(元データ!$E$2:$H$20000,0,MATCH($C$2,元データ!$E$1:$H$1,0)),元データ!$A$2:$A$20000,$A14,元データ!$D$2:$D$20000,$C$3,元データ!$B$2:$B$20000,$P$4,元データ!$C$2:$C$20000,V$5) -> 879301 | W14: =SUMIFS(INDEX(元データ!$E$2:$H$20000,0,MATCH($C$2,元データ!$E$1:$H$1,0)),元データ!$A$2:$A$20000,$A14,元データ!$D$2:$D$20000,$C$3,元データ!$B$2:$B$20000,$P$4,元データ!$C$2:$C$20000,W$5) -> 1968439 | ... AA14: =SUMIFS(INDEX(元データ!$E$2:$H$20000,0,MATCH($C$2,元データ!$E$1:$H$1,0)),元データ!$A$2:$A$20000,$A14,元データ!$D$2:$D$20000,$C$3,元データ!$B$2:$B$20000,$P$4,元データ!$C$2:$C$20000,AA$5) -> 1674765 | AB14: =SUM(P14:AA14) -> 18358394 | AC14: =IFERROR(C14/P14,"") -> 1.0012215 | AD14: =IFERROR(D14/Q14,"") -> 1.1148269 | AE14: =IFERROR(E14/R14,"") -> 1.0654432 | AF14: =IFERROR(F14/S14,"") -> 0.912153 | AG14: =IFERROR(G14/T14,"") -> 1.0000977 | AH14: =IFERROR(H14/U14,"") -> 1.0798965 | AI14: =IFERROR(I14/V14,"") -> 1.1417558 | AJ14: =IFERROR(J14/W14,"") -> 0.81507936 | ... AO14: =IFERROR(O14/AB14,"") -> 0.98881683
A15: =店舗マスタ!A11 -> 岡の宮店 | C15: =SUMIFS(INDEX(元データ!$E$2:$H$20000,0,MATCH($C$2,元データ!$E$1:$H$1,0)),元データ!$A$2:$A$20000,$A15,元データ!$D$2:$D$20000,$C$3,元データ!$B$2:$B$20000,$C$4,元データ!$C$2:$C$20000,C$5) -> 1693532 | D15: =SUMIFS(INDEX(元データ!$E$2:$H$20000,0,MATCH($C$2,元データ!$E$1:$H$1,0)),元データ!$A$2:$A$20000,$A15,元データ!$D$2:$D$20000,$C$3,元データ!$B$2:$B$20000,$C$4,元データ!$C$2:$C$20000,D$5) -> 1567312 | E15: =SUMIFS(INDEX(元データ!$E$2:$H$20000,0,MATCH($C$2,元データ!$E$1:$H$1,0)),元データ!$A$2:$A$20000,$A15,元データ!$D$2:$D$20000,$C$3,元データ!$B$2:$B$20000,$C$4,元データ!$C$2:$C$20000,E$5) -> 2147016 | F15: =SUMIFS(INDEX(元データ!$E$2:$H$20000,0,MATCH($C$2,元データ!$E$1:$H$1,0)),元データ!$A$2:$A$20000,$A15,元データ!$D$2:$D$20000,$C$3,元データ!$B$2:$B$20000,$C$4,元データ!$C$2:$C$20000,F$5) -> 2150599 | G15: =SUMIFS(INDEX(元データ!$E$2:$H$20000,0,MATCH($C$2,元データ!$E$1:$H$1,0)),元データ!$A$2:$A$20000,$A15,元データ!$D$2:$D$20000,$C$3,元データ!$B$2:$B$20000,$C$4,元データ!$C$2:$C$20000,G$5) -> 2172052 | H15: =SUMIFS(INDEX(元データ!$E$2:$H$20000,0,MATCH($C$2,元データ!$E$1:$H$1,0)),元データ!$A$2:$A$20000,$A15,元データ!$D$2:$D$20000,$C$3,元データ!$B$2:$B$20000,$C$4,元データ!$C$2:$C$20000,H$5) -> 1437515 | I15: =SUMIFS(INDEX(元データ!$E$2:$H$20000,0,MATCH($C$2,元データ!$E$1:$H$1,0)),元データ!$A$2:$A$20000,$A15,元データ!$D$2:$D$20000,$C$3,元データ!$B$2:$B$20000,$C$4,元データ!$C$2:$C$20000,I$5) -> 1393171 | J15: =SUMIFS(INDEX(元データ!$E$2:$H$20000,0,MATCH($C$2,元データ!$E$1:$H$1,0)),元データ!$A$2:$A$20000,$A15,元データ!$D$2:$D$20000,$C$3,元データ!$B$2:$B$20000,$C$4,元データ!$C$2:$C$20000,J$5) -> 2561062 | ... N15: =SUMIFS(INDEX(元データ!$E$2:$H$20000,0,MATCH($C$2,元データ!$E$1:$H$1,0)),元データ!$A$2:$A$20000,$A15,元データ!$D$2:$D$20000,$C$3,元データ!$B$2:$B$20000,$C$4,元データ!$C$2:$C$20000,N$5) -> 2013847 | O15: =SUM(C15:N15) -> 26345157 | P15: =SUMIFS(INDEX(元データ!$E$2:$H$20000,0,MATCH($C$2,元データ!$E$1:$H$1,0)),元データ!$A$2:$A$20000,$A15,元データ!$D$2:$D$20000,$C$3,元データ!$B$2:$B$20000,$P$4,元データ!$C$2:$C$20000,P$5) -> 1475237 | Q15: =SUMIFS(INDEX(元データ!$E$2:$H$20000,0,MATCH($C$2,元データ!$E$1:$H$1,0)),元データ!$A$2:$A$20000,$A15,元データ!$D$2:$D$20000,$C$3,元データ!$B$2:$B$20000,$P$4,元データ!$C$2:$C$20000,Q$5) -> 1548525 | R15: =SUMIFS(INDEX(元データ!$E$2:$H$20000,0,MATCH($C$2,元データ!$E$1:$H$1,0)),元データ!$A$2:$A$20000,$A15,元データ!$D$2:$D$20000,$C$3,元データ!$B$2:$B$20000,$P$4,元データ!$C$2:$C$20000,R$5) -> 2388927 | S15: =SUMIFS(INDEX(元データ!$E$2:$H$20000,0,MATCH($C$2,元データ!$E$1:$H$1,0)),元データ!$A$2:$A$20000,$A15,元データ!$D$2:$D$20000,$C$3,元データ!$B$2:$B$20000,$P$4,元データ!$C$2:$C$20000,S$5) -> 2275250 | T15: =SUMIFS(INDEX(元データ!$E$2:$H$20000,0,MATCH($C$2,元データ!$E$1:$H$1,0)),元データ!$A$2:$A$20000,$A15,元データ!$D$2:$D$20000,$C$3,元データ!$B$2:$B$20000,$P$4,元データ!$C$2:$C$20000,T$5) -> 2097862 | U15: =SUMIFS(INDEX(元データ!$E$2:$H$20000,0,MATCH($C$2,元データ!$E$1:$H$1,0)),元データ!$A$2:$A$20000,$A15,元データ!$D$2:$D$20000,$C$3,元データ!$B$2:$B$20000,$P$4,元データ!$C$2:$C$20000,U$5) -> 1396843 | V15: =SUMIFS(INDEX(元データ!$E$2:$H$20000,0,MATCH($C$2,元データ!$E$1:$H$1,0)),元データ!$A$2:$A$20000,$A15,元データ!$D$2:$D$20000,$C$3,元データ!$B$2:$B$20000,$P$4,元データ!$C$2:$C$20000,V$5) -> 1408569 | W15: =SUMIFS(INDEX(元データ!$E$2:$H$20000,0,MATCH($C$2,元データ!$E$1:$H$1,0)),元データ!$A$2:$A$20000,$A15,元データ!$D$2:$D$20000,$C$3,元データ!$B$2:$B$20000,$P$4,元データ!$C$2:$C$20000,W$5) -> 2947360 | ... AA15: =SUMIFS(INDEX(元データ!$E$2:$H$20000,0,MATCH($C$2,元データ!$E$1:$H$1,0)),元データ!$A$2:$A$20000,$A15,元データ!$D$2:$D$20000,$C$3,元データ!$B$2:$B$20000,$P$4,元データ!$C$2:$C$20000,AA$5) -> 2188730 | AB15: =SUM(P15:AA15) -> 27383315 | AC15: =IFERROR(C15/P15,"") -> 1.1479728 | AD15: =IFERROR(D15/Q15,"") -> 1.0121322 | AE15: =IFERROR(E15/R15,"") -> 0.89873655 | AF15: =IFERROR(F15/S15,"") -> 0.94521437 | AG15: =IFERROR(G15/T15,"") -> 1.0353646 | AH15: =IFERROR(H15/U15,"") -> 1.0291171 | AI15: =IFERROR(I15/V15,"") -> 0.98906834 | AJ15: =IFERROR(J15/W15,"") -> 0.86893423 | ... AO15: =IFERROR(O15/AB15,"") -> 0.96208794
A16: =店舗マスタ!A12 -> 川島田店 | C16: =SUMIFS(INDEX(元データ!$E$2:$H$20000,0,MATCH($C$2,元データ!$E$1:$H$1,0)),元データ!$A$2:$A$20000,$A16,元データ!$D$2:$D$20000,$C$3,元データ!$B$2:$B$20000,$C$4,元データ!$C$2:$C$20000,C$5) -> 893197 | D16: =SUMIFS(INDEX(元データ!$E$2:$H$20000,0,MATCH($C$2,元データ!$E$1:$H$1,0)),元データ!$A$2:$A$20000,$A16,元データ!$D$2:$D$20000,$C$3,元データ!$B$2:$B$20000,$C$4,元データ!$C$2:$C$20000,D$5) -> 1054172 | E16: =SUMIFS(INDEX(元データ!$E$2:$H$20000,0,MATCH($C$2,元データ!$E$1:$H$1,0)),元データ!$A$2:$A$20000,$A16,元データ!$D$2:$D$20000,$C$3,元データ!$B$2:$B$20000,$C$4,元データ!$C$2:$C$20000,E$5) -> 1498284 | F16: =SUMIFS(INDEX(元データ!$E$2:$H$20000,0,MATCH($C$2,元データ!$E$1:$H$1,0)),元データ!$A$2:$A$20000,$A16,元データ!$D$2:$D$20000,$C$3,元データ!$B$2:$B$20000,$C$4,元データ!$C$2:$C$20000,F$5) -> 1257823 | G16: =SUMIFS(INDEX(元データ!$E$2:$H$20000,0,MATCH($C$2,元データ!$E$1:$H$1,0)),元データ!$A$2:$A$20000,$A16,元データ!$D$2:$D$20000,$C$3,元データ!$B$2:$B$20000,$C$4,元データ!$C$2:$C$20000,G$5) -> 1085593 | H16: =SUMIFS(INDEX(元データ!$E$2:$H$20000,0,MATCH($C$2,元データ!$E$1:$H$1,0)),元データ!$A$2:$A$20000,$A16,元データ!$D$2:$D$20000,$C$3,元データ!$B$2:$B$20000,$C$4,元データ!$C$2:$C$20000,H$5) -> 857151 | I16: =SUMIFS(INDEX(元データ!$E$2:$H$20000,0,MATCH($C$2,元データ!$E$1:$H$1,0)),元データ!$A$2:$A$20000,$A16,元データ!$D$2:$D$20000,$C$3,元データ!$B$2:$B$20000,$C$4,元データ!$C$2:$C$20000,I$5) -> 769224 | J16: =SUMIFS(INDEX(元データ!$E$2:$H$20000,0,MATCH($C$2,元データ!$E$1:$H$1,0)),元データ!$A$2:$A$20000,$A16,元データ!$D$2:$D$20000,$C$3,元データ!$B$2:$B$20000,$C$4,元データ!$C$2:$C$20000,J$5) -> 1339066 | ... N16: =SUMIFS(INDEX(元データ!$E$2:$H$20000,0,MATCH($C$2,元データ!$E$1:$H$1,0)),元データ!$A$2:$A$20000,$A16,元データ!$D$2:$D$20000,$C$3,元データ!$B$2:$B$20000,$C$4,元データ!$C$2:$C$20000,N$5) -> 1333295 | O16: =SUM(C16:N16) -> 15339997 | P16: =SUMIFS(INDEX(元データ!$E$2:$H$20000,0,MATCH($C$2,元データ!$E$1:$H$1,0)),元データ!$A$2:$A$20000,$A16,元データ!$D$2:$D$20000,$C$3,元データ!$B$2:$B$20000,$P$4,元データ!$C$2:$C$20000,P$5) -> 960135 | Q16: =SUMIFS(INDEX(元データ!$E$2:$H$20000,0,MATCH($C$2,元データ!$E$1:$H$1,0)),元データ!$A$2:$A$20000,$A16,元データ!$D$2:$D$20000,$C$3,元データ!$B$2:$B$20000,$P$4,元データ!$C$2:$C$20000,Q$5) -> 1137595 | R16: =SUMIFS(INDEX(元データ!$E$2:$H$20000,0,MATCH($C$2,元データ!$E$1:$H$1,0)),元データ!$A$2:$A$20000,$A16,元データ!$D$2:$D$20000,$C$3,元データ!$B$2:$B$20000,$P$4,元データ!$C$2:$C$20000,R$5) -> 1475545 | S16: =SUMIFS(INDEX(元データ!$E$2:$H$20000,0,MATCH($C$2,元データ!$E$1:$H$1,0)),元データ!$A$2:$A$20000,$A16,元データ!$D$2:$D$20000,$C$3,元データ!$B$2:$B$20000,$P$4,元データ!$C$2:$C$20000,S$5) -> 1150805 | T16: =SUMIFS(INDEX(元データ!$E$2:$H$20000,0,MATCH($C$2,元データ!$E$1:$H$1,0)),元データ!$A$2:$A$20000,$A16,元データ!$D$2:$D$20000,$C$3,元データ!$B$2:$B$20000,$P$4,元データ!$C$2:$C$20000,T$5) -> 1100945 | U16: =SUMIFS(INDEX(元データ!$E$2:$H$20000,0,MATCH($C$2,元データ!$E$1:$H$1,0)),元データ!$A$2:$A$20000,$A16,元データ!$D$2:$D$20000,$C$3,元データ!$B$2:$B$20000,$P$4,元データ!$C$2:$C$20000,U$5) -> 738482 | V16: =SUMIFS(INDEX(元データ!$E$2:$H$20000,0,MATCH($C$2,元データ!$E$1:$H$1,0)),元データ!$A$2:$A$20000,$A16,元データ!$D$2:$D$20000,$C$3,元データ!$B$2:$B$20000,$P$4,元データ!$C$2:$C$20000,V$5) -> 720345 | W16: =SUMIFS(INDEX(元データ!$E$2:$H$20000,0,MATCH($C$2,元データ!$E$1:$H$1,0)),元データ!$A$2:$A$20000,$A16,元データ!$D$2:$D$20000,$C$3,元データ!$B$2:$B$20000,$P$4,元データ!$C$2:$C$20000,W$5) -> 1604678 | ... AA16: =SUMIFS(INDEX(元データ!$E$2:$H$20000,0,MATCH($C$2,元データ!$E$1:$H$1,0)),元データ!$A$2:$A$20000,$A16,元データ!$D$2:$D$20000,$C$3,元データ!$B$2:$B$20000,$P$4,元データ!$C$2:$C$20000,AA$5) -> 1196515 | AB16: =SUM(P16:AA16) -> 15786599 | AC16: =IFERROR(C16/P16,"") -> 0.93028272 | AD16: =IFERROR(D16/Q16,"") -> 0.92666722 | AE16: =IFERROR(E16/R16,"") -> 1.0154106 | AF16: =IFERROR(F16/S16,"") -> 1.092994 | AG16: =IFERROR(G16/T16,"") -> 0.98605562 | AH16: =IFERROR(H16/U16,"") -> 1.1606932 | AI16: =IFERROR(I16/V16,"") -> 1.067855 | AJ16: =IFERROR(J16/W16,"") -> 0.83447645 | ... AO16: =IFERROR(O16/AB16,"") -> 0.97171006
A17: =店舗マスタ!A13 -> 便船塚店 | C17: =SUMIFS(INDEX(元データ!$E$2:$H$20000,0,MATCH($C$2,元データ!$E$1:$H$1,0)),元データ!$A$2:$A$20000,$A17,元データ!$D$2:$D$20000,$C$3,元データ!$B$2:$B$20000,$C$4,元データ!$C$2:$C$20000,C$5) -> 1851402 | D17: =SUMIFS(INDEX(元データ!$E$2:$H$20000,0,MATCH($C$2,元データ!$E$1:$H$1,0)),元データ!$A$2:$A$20000,$A17,元データ!$D$2:$D$20000,$C$3,元データ!$B$2:$B$20000,$C$4,元データ!$C$2:$C$20000,D$5) -> 2124582 | E17: =SUMIFS(INDEX(元データ!$E$2:$H$20000,0,MATCH($C$2,元データ!$E$1:$H$1,0)),元データ!$A$2:$A$20000,$A17,元データ!$D$2:$D$20000,$C$3,元データ!$B$2:$B$20000,$C$4,元データ!$C$2:$C$20000,E$5) -> 2884722 | F17: =SUMIFS(INDEX(元データ!$E$2:$H$20000,0,MATCH($C$2,元データ!$E$1:$H$1,0)),元データ!$A$2:$A$20000,$A17,元データ!$D$2:$D$20000,$C$3,元データ!$B$2:$B$20000,$C$4,元データ!$C$2:$C$20000,F$5) -> 2266931 | G17: =SUMIFS(INDEX(元データ!$E$2:$H$20000,0,MATCH($C$2,元データ!$E$1:$H$1,0)),元データ!$A$2:$A$20000,$A17,元データ!$D$2:$D$20000,$C$3,元データ!$B$2:$B$20000,$C$4,元データ!$C$2:$C$20000,G$5) -> 2243077 | H17: =SUMIFS(INDEX(元データ!$E$2:$H$20000,0,MATCH($C$2,元データ!$E$1:$H$1,0)),元データ!$A$2:$A$20000,$A17,元データ!$D$2:$D$20000,$C$3,元データ!$B$2:$B$20000,$C$4,元データ!$C$2:$C$20000,H$5) -> 1550086 | I17: =SUMIFS(INDEX(元データ!$E$2:$H$20000,0,MATCH($C$2,元データ!$E$1:$H$1,0)),元データ!$A$2:$A$20000,$A17,元データ!$D$2:$D$20000,$C$3,元データ!$B$2:$B$20000,$C$4,元データ!$C$2:$C$20000,I$5) -> 1400695 | J17: =SUMIFS(INDEX(元データ!$E$2:$H$20000,0,MATCH($C$2,元データ!$E$1:$H$1,0)),元データ!$A$2:$A$20000,$A17,元データ!$D$2:$D$20000,$C$3,元データ!$B$2:$B$20000,$C$4,元データ!$C$2:$C$20000,J$5) -> 2679065 | ... N17: =SUMIFS(INDEX(元データ!$E$2:$H$20000,0,MATCH($C$2,元データ!$E$1:$H$1,0)),元データ!$A$2:$A$20000,$A17,元データ!$D$2:$D$20000,$C$3,元データ!$B$2:$B$20000,$C$4,元データ!$C$2:$C$20000,N$5) -> 2410696 | O17: =SUM(C17:N17) -> 29743604 | P17: =SUMIFS(INDEX(元データ!$E$2:$H$20000,0,MATCH($C$2,元データ!$E$1:$H$1,0)),元データ!$A$2:$A$20000,$A17,元データ!$D$2:$D$20000,$C$3,元データ!$B$2:$B$20000,$P$4,元データ!$C$2:$C$20000,P$5) -> 1850143 | Q17: =SUMIFS(INDEX(元データ!$E$2:$H$20000,0,MATCH($C$2,元データ!$E$1:$H$1,0)),元データ!$A$2:$A$20000,$A17,元データ!$D$2:$D$20000,$C$3,元データ!$B$2:$B$20000,$P$4,元データ!$C$2:$C$20000,Q$5) -> 1866846 | R17: =SUMIFS(INDEX(元データ!$E$2:$H$20000,0,MATCH($C$2,元データ!$E$1:$H$1,0)),元データ!$A$2:$A$20000,$A17,元データ!$D$2:$D$20000,$C$3,元データ!$B$2:$B$20000,$P$4,元データ!$C$2:$C$20000,R$5) -> 2823168 | S17: =SUMIFS(INDEX(元データ!$E$2:$H$20000,0,MATCH($C$2,元データ!$E$1:$H$1,0)),元データ!$A$2:$A$20000,$A17,元データ!$D$2:$D$20000,$C$3,元データ!$B$2:$B$20000,$P$4,元データ!$C$2:$C$20000,S$5) -> 2367121 | T17: =SUMIFS(INDEX(元データ!$E$2:$H$20000,0,MATCH($C$2,元データ!$E$1:$H$1,0)),元データ!$A$2:$A$20000,$A17,元データ!$D$2:$D$20000,$C$3,元データ!$B$2:$B$20000,$P$4,元データ!$C$2:$C$20000,T$5) -> 2170226 | U17: =SUMIFS(INDEX(元データ!$E$2:$H$20000,0,MATCH($C$2,元データ!$E$1:$H$1,0)),元データ!$A$2:$A$20000,$A17,元データ!$D$2:$D$20000,$C$3,元データ!$B$2:$B$20000,$P$4,元データ!$C$2:$C$20000,U$5) -> 1617550 | V17: =SUMIFS(INDEX(元データ!$E$2:$H$20000,0,MATCH($C$2,元データ!$E$1:$H$1,0)),元データ!$A$2:$A$20000,$A17,元データ!$D$2:$D$20000,$C$3,元データ!$B$2:$B$20000,$P$4,元データ!$C$2:$C$20000,V$5) -> 1375302 | W17: =SUMIFS(INDEX(元データ!$E$2:$H$20000,0,MATCH($C$2,元データ!$E$1:$H$1,0)),元データ!$A$2:$A$20000,$A17,元データ!$D$2:$D$20000,$C$3,元データ!$B$2:$B$20000,$P$4,元データ!$C$2:$C$20000,W$5) -> 3183885 | ... AA17: =SUMIFS(INDEX(元データ!$E$2:$H$20000,0,MATCH($C$2,元データ!$E$1:$H$1,0)),元データ!$A$2:$A$20000,$A17,元データ!$D$2:$D$20000,$C$3,元データ!$B$2:$B$20000,$P$4,元データ!$C$2:$C$20000,AA$5) -> 2391292 | AB17: =SUM(P17:AA17) -> 30090246 | AC17: =IFERROR(C17/P17,"") -> 1.0006805 | AD17: =IFERROR(D17/Q17,"") -> 1.1380596 | AE17: =IFERROR(E17/R17,"") -> 1.0218032 | AF17: =IFERROR(F17/S17,"") -> 0.95767432 | AG17: =IFERROR(G17/T17,"") -> 1.0335684 | AH17: =IFERROR(H17/U17,"") -> 0.95829248 | AI17: =IFERROR(I17/V17,"") -> 1.0184636 | AJ17: =IFERROR(J17/W17,"") -> 0.84144528 | ... AO17: =IFERROR(O17/AB17,"") -> 0.98847992
